Workbook

Sheet _Index
A1: SPUR Combined Model (v7 + Model 3)
A3: MODEL 2: Project-Level DCF (Developer IRR)
A4: Inputs | B4: Global scenario levers (queue wait, ITC, credit type) + shared parameters
A5: Configurations | B5: Per-configuration CAPEX, CF, degradation, operating life (Solar/Wind/Geo)
A6: Capitalization | B6: Tax equity / debt / developer equity sizing: 6 columns (Base+Coloc × 3 configs)
A7: SolarBase | B7: Solar+BESS 100MW cash flow waterfall: project idle during queue wait
A8: SolarColoc | B8: Solar+BESS 100MW cash flow waterfall: BTM sales during queue wait
A9: WindBase | B9: Wind+BESS 150MW cash flow waterfall: project idle during queue wait
A10: WindColoc | B10: Wind+BESS 150MW cash flow waterfall: BTM sales during queue wait
A11: GeoBase | B11: Geothermal+BESS 100MW cash flow waterfall: project idle during queue wait
A12: GeoColoc | B12: Geothermal+BESS 100MW cash flow waterfall: BTM sales during queue wait
A13: Results | B13: Live IRR/NPV/Value Bridge + Queue×ITC sweep tables (all 3 configs)
A15: MODEL 3: Data Center Electricity Cost (H2 Test)
A16: M3_Inputs | B16: DC load, generation supply, sourced & placeholder prices
A17: M3_Coverage | B17: Energy-balance coverage ratio by configuration
A18: M3_StructA_B | B18: Structure A (utility tariff) & Structure B (sleeved grid PPA) all-in cost
A19: M3_StructC | B19: Structure C (BTM co-location) Phase 1 & Phase 2 all-in cost
A20: M3_Results | B20: Cost comparison + H2 savings test (20-35% threshold)
A22: MODEL 1: Electricity Price Benchmark (Stage 1)
A23: M1_Inputs | B23: All DMM-sourced data points (annual, quarterly, hourly, GHG) with URL citations
A24: M1_Benchmarks | B24: Derivation of P_low / P_avg / P_high from DMM hourly & annual statistics
A25: M1_Scenarios | B25: 3×3 matrix (load × carbon) = 9 price scenarios; spot-to-PPA bridge; solar capture caveat
A26: M1_Notes | B26: Methodology: why DMM instead of raw OASIS, binning proxy, limitations, replication path
A28: MODEL 4: Bilateral BTM PPA Pricing (Negotiation Zone)
A29: M4_LCOE | B29: LCOE per configuration (gross & net of tax equity): the developer's price floor
A30: M4_Bounds | B30: Floor vs three ceilings (all-in / energy-only / spot+wires); zone width; viability tests
A31: M4_Pricing | B31: Three price-setting methods; α lever; two-sided test; analytical mutually-acceptable range
A32: M4_Notes | B32: Methodology, findings (incl. $60 < LCOE for solar/wind), open loop-closure items
A34: FIGURES (native Excel charts; data + chart on each sheet)
A35: Fig2_Breakeven | B35: Levered IRR vs queue wait, 6 panels (lever × config); static sweep values
A36: Fig3_Zone | B36: Price floor / ceiling / acceptable range stacked bar; LIVE links to M4
A37: Fig4_Alpha | B37: IRR and DC saving vs bargaining share α, 3 panels; static sweep values

Sheet M1_Inputs
A1: Model 1: Electricity Price Benchmark: INPUTS (CAISO DMM Published Statistics)
A2: Blue = hardcoded from published DMM reports. Every value carries a source + URL in column E. See M1_Notes for methodology deviation from original Stage 1 spec.
A4: SEC 1: ANNUAL LOAD-WEIGHTED AVERAGE PRICES: California region
A5: Parameter | B5: Value | C5: Unit | D5: Year | E5: Source
A6: CA region day-ahead market avg price | B6: 41 | C6: $/MWh | D6: 2024 | E6: CAISO DMM 2024 Annual Report (Aug 7, 2025), Executive Summary p.3: 'day-ahead market prices averaged $41/MWh'. https://www.caiso.com/documents/2024-annual-report-on-market-issues-and-performance-aug-07-2025.pdf
A7: CA region 15-min market avg price | B7: 41.1 | C7: $/MWh | D7: 2024 | E7: CAISO DMM 2024 Annual Report, Figure E.2 table: California 41.1, -36% vs 2023. Same URL.
A8: CA region day-ahead market avg price | B8: 39 | C8: $/MWh | D8: 2025 | E8: CAISO DMM 2025 Annual Report (Jun 26, 2026), Executive Summary p.3: 'Day-ahead market prices averaged about $39/MWh'. https://www.caiso.com/documents/2025-annual-report-on-market-issues-and-performance.pdf
A9: CA region 15-min market avg price | B9: 38.32 | C9: $/MWh | D9: 2025 | E9: CAISO DMM 2025 Annual Report, Figure E.2 table: California $38.32, -7% vs 2024. Same URL.
A10: CAISO total wholesale cost per MWh of load | B10: 42 | C10: $/MWh | D10: 2025 | E10: CAISO DMM 2025 Annual Report, p.4: 'Total wholesale costs for the CAISO balancing area decreased by about 6 percent to $8.45 billion, or about $42/MWh'. Same URL.
A11: Implied 2023 CA DA avg (back-calc from -36% YoY) | B11: =B7/(1-0.36) -> 64.21875 | C11: $/MWh | D11: 2023 | E11: Calc: 2024 value / (1 - 0.36). DMM 2024 Annual Report states CA prices fell 36% from 2023. Use as high-gas-price sensitivity only.
A13: SEC 2: QUARTERLY PRICES: seasonal shape (CAISO balancing area)
A14: Parameter | B14: Value | C14: Unit | D14: Year | E14: Source
A15: Q1 2024 avg (DA/15-min/5-min blended) | B15: 43 | C15: $/MWh | D15: 2024 Q1 | E15: CAISO DMM Q1 2024 Report (Oct 11, 2024): 'average price of the three markets this quarter decreased to $43/MWh from $93/MWh in Q1 2023'. https://www.caiso.com/documents/2024-first-quarter-report-on-market-issues-and-performance-oct-11-2024.pdf
A16: Q2 2024 avg (15-min, WEIM-wide) | B16: 19 | C16: $/MWh | D16: 2024 Q2 | E16: CAISO DMM Q2 2024 Report (Nov 22, 2024): 'Prices in both the 15-minute and 5-minute markets averaged around $19/MWh, down 40% vs Q2 2023'. WEIM-wide figure; CA-specific likely ~$5-8 higher due to GHG. https://www.caiso.com/documents/2024-second-quarter-report-on-market-issues-and-performance-nov-22-2024.pdf
A17: Q3 2024 CAISO day-ahead avg | B17: 48 | C17: $/MWh | D17: 2024 Q3 | E17: CAISO DMM Q3 2024 Report (Dec 23, 2024), Sec 3.3 p.27: 'day-ahead prices averaged $48/MWh, 15-minute $47/MWh, 5-minute $40/MWh'. https://www.caiso.com/documents/2024-third-quarter-report-on-market-issues-and-performance-dec-23-2024.pdf
A18: Q3 2024 CA region 15-min avg | B18: 47.5 | C18: $/MWh | D18: 2024 Q3 | E18: CAISO DMM Q3 2024 Report, Figure E.1 table: California 47.5, -27% vs Q3 2023. Same URL.
A19: Q3 2024 July monthly DA peak-hours avg | B19: 58 | C19: $/MWh | D19: 2024 Jul | E19: CAISO DMM Q3 2024 Report, Figure 3.12 table: CAISO Jul $58 / Aug $42 / Sep $40 (peak hours HE7-22). Same URL.
A20: Q4 2025 WEIM 15-min avg | B20: 36 | C20: $/MWh | D20: 2025 Q4 | E20: CAISO DMM Q4 2025 Report (Mar 30, 2026): 'Overall 15-minute market prices across WEIM averaged $36/MWh, down 7% vs Q4 2024'. https://www.caiso.com/documents/2025-fourth-quarter-report-on-market-issues-and-performance.pdf
A22: SEC 3: HOURLY 15-MIN MARKET PRICES: Q3 2024 (Jul–Sep), CAISO DLAPs
A23: Source: CAISO DMM Q3 2024 Report, Table 3.3 'Hourly 15-minute market prices (July–September)', p.26. Values are load-weighted hourly averages at PG&E and SCE default load aggregation points. Same URL as SEC 2 Q3 row.
A24: Hour Ending | B24: PG&E DLAP ($/MWh) | C24: SCE DLAP ($/MWh) | D24: Blend ($/MWh) | E24: Net-load regime
A25: 1 | B25: 40 | C25: 40 | D25: =AVERAGE(B25,C25) -> 40 | E25: Overnight
A26: 2 | B26: 38 | C26: 38 | D26: =AVERAGE(B26,C26) -> 38 | E26: Overnight
A27: 3 | B27: 36 | C27: 36 | D27: =AVERAGE(B27,C27) -> 36 | E27: Overnight
A28: 4 | B28: 35 | C28: 35 | D28: =AVERAGE(B28,C28) -> 35 | E28: Overnight
A29: 5 | B29: 35 | C29: 35 | D29: =AVERAGE(B29,C29) -> 35 | E29: Overnight
A30: 6 | B30: 39 | C30: 38 | D30: =AVERAGE(B30,C30) -> 38.5 | E30: Overnight
A31: 7 | B31: 40 | C31: 40 | D31: =AVERAGE(B31,C31) -> 40 | E31: Overnight
A32: 8 | B32: 32 | C32: 30 | D32: =AVERAGE(B32,C32) -> 31 | E32: Morning ramp
A33: 9 | B33: 27 | C33: 21 | D33: =AVERAGE(B33,C33) -> 24 | E33: Mid-day solar
A34: 10 | B34: 26 | C34: 19 | D34: =AVERAGE(B34,C34) -> 22.5 | E34: Mid-day solar
A35: 11 | B35: 25 | C35: 20 | D35: =AVERAGE(B35,C35) -> 22.5 | E35: Mid-day solar
A36: 12 | B36: 27 | C36: 21 | D36: =AVERAGE(B36,C36) -> 24 | E36: Mid-day solar
... A48: 24 | B48: 42 | C48: 42 | D48: =AVERAGE(B48,C48) -> 42 | E48: Late evening
A50: SEC 4: GREENHOUSE GAS PRICE & IMPLIED MARGINAL EMISSION RATE
A51: Parameter | B51: Value | C51: Unit | D51: Year | E51: Source
A52: CA GHG allowance price (bilateral avg) | B52: 38.09 | C52: $/mtCO2e | D52: 2024 | E52: CAISO DMM 2024 Annual Report, p.2: 'California greenhouse gas allowances averaged $38.09/mtCO2e in bilateral markets in 2024'.
A53: GHG cost impact on efficient gas unit | B53: 16.19 | C53: $/MWh | D53: 2024 | E53: CAISO DMM 2024 Annual Report, p.2: 'This represented an additional cost of about $16.19/MWh for a relatively efficient gas unit'.
A54: CA GHG allowance price (bilateral avg) | B54: 29.89 | C54: $/mtCO2e | D54: 2025 | E54: CAISO DMM 2025 Annual Report, p.2: 'California greenhouse gas allowance prices averaged about $29.89/mtCO2e in 2025, down 22 percent from 2024'.
A55: GHG cost impact on efficient gas unit | B55: 12.7 | C55: $/MWh | D55: 2025 | E55: CAISO DMM 2025 Annual Report, p.2: 'representing an incremental cost of about $12.70/MWh for a relatively efficient gas unit'.
...

Sheet M1_Benchmarks
A1: Model 1: Three Load-Level Price Benchmarks (derived from DMM hourly & annual statistics)
A2: Green = pulled from M1_Inputs. Black = formula. Yellow = headline benchmark output feeding M1_Scenarios. Hour-bin definitions are a judgment call: see M1_Notes §3.
A4: SEC 1: HOUR-BIN DEFINITIONS (mapping framework load percentiles → DMM hourly regime)
A5: Benchmark | B5: Framework definition | C5: DMM proxy (Q3 2024 Table 3.3 hours) | D5: Hours in bin | E5: Rationale
A6: LOW | B6: Bottom 20th pctile system load; spring shoulder, mild weather, high solar | C6: HE10–HE13 (mid-day solar trough) | D6: 10,11,12,13 | E6: Framework text describes high-solar hours, i.e. low NET load. Mid-day trough is the empirical minimum in DMM Table 3.3 and the regime where solar/wind projects would actually be selling. Overnight hours (HE1-7, ~$35-40) are low GROSS load but not the framework's intent.
A7: AVERAGE | B7: 30th–70th pctile system load; typical demand, moderate weather | C7: Annual load-weighted DA average (2024 & 2025) | D7: all 8,760 | E7: Load-weighted annual mean already integrates the full distribution; DMM publishes this directly. Two-year average dampens single-year gas-price idiosyncrasy (2024 unusually low gas).
A8: HIGH | B8: Top 10th pctile system load; summer peak, extreme heat, evening ramp | C8: HE19–HE21 (evening net-load peak) | D8: 19,20,21 | E8: DMM Q3 2024 confirms 'prices peaked at HE20 when demand was still high but solar substantially below its peak'. Summer evening ramp is top-decile net load. Excludes extreme scarcity tail (>$250, only 0.6% of Q3 intervals).
A10: SEC 2: LOW BENCHMARK: mid-day solar trough
A11: PG&E DLAP, HE10–13 avg | B11: =AVERAGE(M1_Inputs!B34:B37) -> 26.25 | C11: $/MWh
A12: SCE DLAP, HE10–13 avg | B12: =AVERAGE(M1_Inputs!C34:C37) -> 20.75 | C12: $/MWh
A13: Blended (equal weight PG&E/SCE) | B13: =AVERAGE(B11,B12) -> 23.5 | C13: $/MWh
A14: Cross-check: Q2 2024 WEIM 15-min avg | B14: =M1_Inputs!B15 -> 43 | C14: $/MWh | D14: Spring-shoulder quarterly avg; WEIM-wide so ~$5–8 below CA. Consistent with mid-day blend.
A15: Cross-check: framework prior range | B15: 15 – 30 | C15: $/MWh | D15: Framework Sec 1.2 expected range. Blended value falls inside.
A16: LOW BENCHMARK (P_low) | B16: =ROUND(B13,0) -> 24 | C16: $/MWh | D16: Rounded to nearest $1. Mid-day Q3 blend; Q3 is the season where mid-day solar depression is strongest, so this is a conservative (low) value for annual mid-day.
A18: SEC 3: AVERAGE BENCHMARK: annual load-weighted DA
A19: 2024 CA DA avg | B19: =M1_Inputs!$B$6 -> 41 | C19: $/MWh
A20: 2025 CA DA avg | B20: =M1_Inputs!$B$8 -> 39 | C20: $/MWh
A21: 2-year average | B21: =AVERAGE(B19,B20) -> 40 | C21: $/MWh
A22: Cross-check: 2023 implied (high gas year) | B22: =M1_Inputs!$B$11 -> 64.21875 | C22: $/MWh | D22: Excluded from base benchmark: 2023 gas prices were anomalously high (SoCal Citygate $5.12 vs $2.14 in 2024). Available as upside sensitivity.
A23: Cross-check: framework prior range | B23: 35 – 55 | C23: $/MWh | D23: Framework Sec 1.2. 2-yr average falls inside.
A24: AVERAGE BENCHMARK (P_avg) | B24: =ROUND(B21,0) -> 40 | C24: $/MWh | D24: Rounded to nearest $1.
A26: SEC 4: HIGH BENCHMARK: summer evening net-load peak
A27: PG&E DLAP, HE19–21 avg | B27: =AVERAGE(M1_Inputs!B43:B45) -> 95 | C27: $/MWh
A28: SCE DLAP, HE19–21 avg | B28: =AVERAGE(M1_Inputs!C43:C45) -> 82 | C28: $/MWh
A29: Blended (equal weight PG&E/SCE) | B29: =AVERAGE(B27,B28) -> 88.5 | C29: $/MWh
A30: Cross-check: HE20 DA load-weighted (Q3 2024) | B30: =M1_Inputs!$B$68 -> 120 | C30: $/MWh | D30: Single peak hour; DA slightly above 15-min in this hour. Blend of HE19-21 is the fairer top-decile representation.
A31: Cross-check: framework prior range | B31: 60 – 120 | C31: $/MWh | D31: Framework Sec 1.2. Blended value falls inside.
A32: HIGH BENCHMARK (P_high) | B32: =ROUND(B29,0) -> 89 | C32: $/MWh | D32: Rounded to nearest $1. Q3-only; represents the summer regime where top-decile load occurs.
A34: SEC 5: SUMMARY: three base benchmarks (feed M1_Scenarios)
A35: Benchmark | B35: $/MWh | C35: vs. P_avg | D35: Framework range | E35: Inside range?
A36: P_low | B36: =B16 -> 24 | C36: =B36/$B$24-1 -> -0.4 | D36: $15–$30 | E36: =IF(AND(B36>=15,B36<=30),"YES","NO") -> YES
A37: P_avg | B37: =B24 -> 40 | C37: =B37/$B$24-1 -> 0 | D37: $35–$55 | E37: =IF(AND(B37>=35,B37<=55),"YES","NO") -> YES
A38: P_high | B38: =B32 -> 89 | C38: =B38/$B$24-1 -> 1.225 | D38: $60–$120 | E38: =IF(AND(B38>=60,B38<=120),"YES","NO") -> YES

Sheet M1_Scenarios
A1: Model 1: Nine Price Scenarios (3 load levels × 3 carbon prices) + PPA Bridge
A2: This is the Stage 1 output. Carbon adders are INCREMENTAL to the CA cap-and-trade cost already embedded in observed prices (framework Sec 1.2: '$0/ton = status quo').
A4: SEC 1: CARBON OVERLAY PARAMETERS
A5: Marginal emission rate (DMM-implied, efficient CCGT) | B5: =M1_Inputs!$B$58 -> 0.42496861 | C5: tCO2e/MWh | D5: From M1_Inputs SEC 4. Framework assumed 0.4–0.6; DMM data pins it at the low end (efficient CCGT sets the margin).
A6: Already-embedded CA carbon cost (2025 avg) | B6: =M1_Inputs!$B$54 -> 29.89 | C6: $/tCO2e | D6: Context only: observed prices already include this. Scenario adders stack on top.
A8: Carbon scenario | B8: Incremental $/tCO2e | C8: Adder $/MWh | D8: Framework rationale
A9: C0: status quo | B9: 0 | C9: =B9*$B$5 -> 0 | D9: Current CA cap-and-trade only (already in observed prices)
A10: C30: moderate | B10: 30 | C10: =B10*$B$5 -> 12.749058 | D10: Framework Sec 1.2: cap-and-trade escalation or federal carbon tax
A11: C60: aggressive | B11: 60 | C11: =B11*$B$5 -> 25.498116 | D11: Framework Sec 1.2: aggressive decarbonization / high SCC
A13: SEC 2: NINE-SCENARIO PRICE MATRIX ($/MWh): STAGE 1 OUTPUT
A14: Load level ↓ / Carbon → | B14: C0: status quo | C14: C30: moderate | D14: C60: aggressive
A15: LOW (mid-day solar trough) | B15: =M1_Benchmarks!$B$16+$C$9 -> 24 | C15: =M1_Benchmarks!$B$16+$C$10 -> 36.749058 | D15: =M1_Benchmarks!$B$16+$C$11 -> 49.498116
A16: AVERAGE (annual load-wtd) | B16: =M1_Benchmarks!$B$24+$C$9 -> 40 | C16: =M1_Benchmarks!$B$24+$C$10 -> 52.749058 | D16: =M1_Benchmarks!$B$24+$C$11 -> 65.498116
A17: HIGH (evening net-load peak) | B17: =M1_Benchmarks!$B$32+$C$9 -> 89 | C17: =M1_Benchmarks!$B$32+$C$10 -> 101.74906 | D17: =M1_Benchmarks!$B$32+$C$11 -> 114.49812
A19: Scenario naming for Model 2/3/4 runs: {L,A,H} × {C0,C30,C60} → e.g. 'A-C0' = average load, status-quo carbon = base case.
A21: SEC 3: SPOT-TO-PPA BRIDGE: how Model 1 connects to the $72/MWh already in Model 2
A22: Model 2 v7 uses a $72/MWh hybrid (solar+storage) PPA price sourced from LBNL Utility-Scale Solar. A PPA is a 15–20 yr fixed-price forward contract; spot DA prices are the annual realized average. The two are not the same quantity. This block reconciles them so the paper can state the relationship explicitly.
A23: Model 2 grid PPA price (LBNL hybrid PPA) | B23: =Inputs!B18 -> 72 | C23: $/MWh | D23: Cross-sheet link to Model 2 Inputs. LBNL Utility-Scale Solar 2024 Ed., solar+storage PPA levels. https://emp.lbl.gov/utility-scale-solar
A24: P_avg spot benchmark (this model) | B24: =M1_Benchmarks!$B$24 -> 40 | C24: $/MWh
A25: Implied PPA premium over spot | B25: =B23-B24 -> 32 | C25: $/MWh
A26: Implied PPA premium (%) | B26: =B23/B24-1 -> 0.8 | C26: frac | D26: Premium reflects: (a) 15-20yr price certainty, (b) storage capacity value in a hybrid PPA, (c) RA attributes bundled with energy, (d) counterparty credit. Not a contradiction: a PPA above spot is the normal market structure.
A28: Which price feeds Model 2 grid revenue?
A29: Option A: keep $72 PPA (current v7) | B29: =B23 -> 72 | C29: $/MWh | D29: Post-COD revenue assumes developer signs a contracted PPA. Consistent with how utility-scale projects are actually financed (lenders require contracted revenue). RECOMMENDED for base case.
A30: Option B: merchant at P_avg | B30: =M1_Benchmarks!$B$24 -> 40 | C30: $/MWh | D30: Post-COD revenue assumes merchant exposure to spot. Lower revenue, higher risk. Use as downside sensitivity: this is the 'no PPA available' case.
A31: Option C: merchant at P_high (peak-shaped) | B31: =M1_Benchmarks!$B$32 -> 89 | C31: $/MWh | D31: Only valid for dispatchable output (BESS discharge or geothermal) that can target evening peak. Not applicable to as-generated solar.
A33: SEC 4: SOLAR CAPTURE RATE: material caveat for Solar+BESS configuration
A34: SP15 solar capture rate (2024) | B34: =M1_Inputs!B65 -> 0.3 | C34: frac of ATC
A35: Solar-weighted realized spot (P_avg × capture) | B35: =M1_Benchmarks!$B$24*B34 -> 12 | C35: $/MWh | D35: If a solar project sold merchant with no storage, its generation-weighted price would be roughly this. This is why Model 2 solar baseline IRR is weak and why BESS is structurally required: it shifts output from P_low hours toward P_high hours.

Sheet M1_Notes
A1: Model 1: Methodology Notes and Deviation from Original Stage 1 Specification
A3: §1 What the proposal specified
A4: Revised Proposal (May 2026), Stage 1: download CAISO OASIS day-ahead hourly LMP for 2023–2025 at TH_SP15/TH_NP15, bin each hour by concurrent system load percentile (bottom 20% / 30–70% / top 10%), compute load-weighted average LMP per bin, then overlay three carbon prices. Output: 9 benchmark prices.
A6: §2 What was actually done, and why
A7: Benchmarks are constructed from CAISO Department of Market Monitoring (DMM) published statistics: the 2024 and 2025 Annual Reports and the 2024 Q1–Q3 and 2025 Q4 quarterly reports: rather than from raw OASIS hourly downloads. Reasons: (a) DMM figures are official, load-weighted, and independently computed by CAISO's market monitor, which is a stronger provenance for a citable benchmark than a student-processed OASIS extract; (b) DMM publishes exactly the aggregates the framework needs (annual load-weighted DA mean, hourly load-weighted 15-min profile, GHG cost per MWh); (c) raw OASIS processing was deferred to preserve time for Models 2–4, which are the analytical core. The raw-OASIS path remains available as a robustness check (see §6).
A9: §3 Binning: load percentile vs. hour-of-day proxy
A10: The framework bins by system-load percentile. DMM does not publish load-percentile-binned prices, so this model uses hour-of-day regimes from DMM Q3 2024 Table 3.3 as the proxy. The framework's own descriptions: LOW = 'spring shoulder, high solar output hours'; HIGH = 'summer peak, evening ramp': are net-load concepts, and net load in CAISO is a function of hour-of-day far more than of gross load. Mid-day solar trough (HE10–13) is the empirical minimum in the DMM table; evening ramp (HE19–21) is the empirical maximum. The mapping is therefore faithful to the framework's economic intent, but it is a judgment call and should be stated as such in the paper.
A12: §4 Known limitations
A13: (a) Hourly profile is Q3 2024 only. Q3 has the deepest mid-day depression and the highest evening peak, so P_low is a conservative low and P_high is a conservative high relative to a full-year hourly average. P_avg is unaffected (annual figure). (b) 15-minute market hourly averages are used for the hourly profile because DMM publishes that table; DA and 15-min converge on average (DMM Q3 2024 §3.3: 'typically tend to converge on average due to convergence bidding'), so the substitution is minor. (c) PG&E and SCE DLAPs are blended equally; a project-specific run should weight by actual node (Salton Sea geothermal and Tehachapi wind are SP15/SCE-side; solar 'various'). (d) 2023 is excluded from P_avg because DMM documents 2023 as a gas-price anomaly (SoCal Citygate $5.12 vs $2.14/MMBtu); it is retained as an explicit high-price sensitivity.
A15: §5 Carbon overlay
A16: Adders are computed as incremental $/tCO2e × marginal emission rate. The emission rate (0.425 tCO2e/MWh) is not assumed: it is back-calculated from DMM's own statement of the GHG cost impact on 'a relatively efficient gas unit' in both 2024 ($16.19/MWh ÷ $38.09/t) and 2025 ($12.70/MWh ÷ $29.89/t), which agree to three decimals. This pins the framework's 0.4–0.6 range to its lower bound. Adders are incremental to the CA cap-and-trade cost already embedded in observed prices; the C0 scenario is the observed price, not a carbon-free counterfactual.
A18: §6 Path to full OASIS replication (if time permits)
... A22: → Model 2 (DCF): the grid PPA price stays at $72/MWh (LBNL contracted hybrid PPA) for the base case; P_avg and P_high are sensitivity inputs for merchant-exposure cases. See M1_Scenarios SEC 3 for the reconciliation. → Model 3 (DC cost): Structure B 'PPA energy price' placeholder ($70) can be replaced by the Model 2 PPA link; P_avg is the VPPA settlement reference. → Model 4 (BTM pricing): P_avg + T&D stack (from Model 3 Structure B) forms the grid-alternative ceiling; the carbon scenarios shift the ceiling upward, widening the negotiation zone.

Sheet Inputs
A1: SPUR Preliminary Co-location Model v7: per-configuration tabs
A2: Three yellow levers apply to ALL configurations simultaneously (keeps cross-config comparison consistent). Blue = editable. $ in millions.
A4: SCENARIO LEVERS (GLOBAL)
A5: Queue wait (mech. completion -> COD), years | B5: 4 | C5: Test 2/4/6/8 (LBNL Queued Up 2025: https://emp.lbl.gov/queues)
A6: ITC rate | B6: 0.3 | C6: 0% = OBBBA Scenario D (zero credit under EITHER credit type); 30% = full rate w/ PWA
A7: Credit type (1=ITC, 2=PTC) | B7: 1 | C7: Framework 2.3.5: run both; PTC uses full depreciable basis
A8: SHARED PARAMETERS
A9: PTC rate ($/MWh, full rate w/ PWA) | B9: 15 | C9: $0.015/kWh, 10-yr duration (Framework 2.3.4; inflation adjustment omitted)
A10: BESS delivery loss (RTE approx.) | B10: 0.01 | C10: Annual approximation of round-trip losses
A11: Debt interest rate | B11: 0.055 | C11: Framework 2.3.1: 5-7% range
A12: Debt tenor (years) | B12: 20 | C12: Framework 2.3.1
A13: Target DSCR (debt sizing) | B13: 1.35 | C13: Framework 2.7
A14: Max leverage (% of total capital) | B14: 0.55 | C14: Framework 2.3.1: 50-55%; binds when DSCR-sized debt exceeds it (wind, geothermal)
A15: Combined tax rate (fed + CA) | B15: 0.2984 | C15: 21% federal + 8.84% CA
A16: Tax equity pay rate (per $ benefit PV) | B16: 0.8 | C16: TE pays ~80c per $1 PV of ITC + PTC + MACRS shield
A17: MACRS PV discount rate | B17: 0.07 | C17: Assumption
A18: Grid hybrid PPA price ($/MWh) | B18: 72 | C18: LBNL Utility-Scale Solar (hybrid PPA levels): https://emp.lbl.gov/utility-scale-solar
A19: BTM PPA price ($/MWh) | B19: 60 | C19: ~17% discount, within 10-20% industry range (Framework 4.3)
A20: Asset management (% of revenue) | B20: 0.015 | C20: Framework 2.6
... A27: BTM price source (1 = global B19, 2 = Model 4 per-config) | B27: 2 | C27: Set 1 to reproduce v7 results at flat $60. Set 2 to close the M4 to M2 loop.

Sheet Configurations
A1: Configuration library: each parameter feeds its configuration's tabs directly
A3: Parameter | B3: Solar+BESS 100MW | C3: Wind+BESS 150MW | D3: Geothermal+BESS 100MW | E3: Source / note
A4: Capacity (MW) | B4: 100 | C4: 150 | D4: 100 | E4: Solar/Geothermal: Framework 2.2.1. Wind: 150 MW scale variant (user-specified)
A5: Capacity factor | B5: 0.275 | C5: 0.35 | D5: 0.9 | E5: Solar: CA midpoint. Wind: upper Tehachapi 30-35%. Geothermal: 90%+ Salton Sea/Imperial Valley (NREL ATB 2024: https://atb.nrel.gov/electricity/2024/technologies)
A6: Annual degradation | B6: 0.005 | C6: 0.002 | D6: 0 | E6: Framework 2.5.2 (geothermal ~0%)
A7: Availability | B7: 0.98 | C7: 0.96 | D7: 0.95 | E7: Framework 2.5.2
A8: Electrical losses | B8: 0.025 | C8: 0.025 | D8: 0.025 | E8: Framework 2.5.2
A9: Total CAPEX ($mm) | B9: 197 | C9: 321.4 | D9: 568.25 | E9: Solar: Framework 2.2.3. Wind: $1,350/kW x150 + BESS 75MW/300MWh @$1,250/kW + dev 4% + land + intercon. Geothermal: $5,000/kW x100 + BESS 25MW/50MWh + dev 4% + land + intercon (NREL ATB 2024 midpoints)
A10: Qualified investment ($mm) | B10: 180 | C10: 296.25 | D10: 531.25 | E10: Generation + BESS only (Framework 2.2.4)
A11: Microgrid CAPEX ($mm) | B11: 12 | C11: 18 | D11: 12 | E11: $120/kW midpoint of $50-150/kW x capacity
A12: Fixed O&M, gen + BESS ($mm/yr) | B12: 3 | C12: 6.375 | D12: 4.625 | E12: Framework 2.6 midpoints per configuration
A13: Land lease + insurance ($mm/yr) | B13: 1.088 | C13: 1.586 | D13: 2.573 | E13: $0.3mm land + 0.4% of CAPEX insurance
A14: Microgrid O&M ($mm/yr) | B14: 0.75 | C14: 1.125 | D14: 0.75 | E14: $7.5/kW-yr x capacity
A15: Operating life (years) | B15: 25 | C15: 25 | D15: 30 | E15: Framework 2.1: 25 yrs solar/wind, 30 yrs geothermal
A16: BTM PPA price, effective ($/MWh) | B16: =IF(Inputs!$B$27=1,Inputs!$B$19,M4_Pricing!B19) -> 121.25624 | C16: =IF(Inputs!$B$27=1,Inputs!$B$19,M4_Pricing!C19) -> 116.35372 | D16: =IF(Inputs!$B$27=1,Inputs!$B$19,M4_Pricing!D19) -> 108.93487 | E16: Switch on Inputs!B27. Source 2 pulls the Model 4 selected price (M4_Pricing SEC 3), which depends on the method selector and alpha lever there. Feeds the queue-wait revenue in each Coloc tab.
A17: BTM PPA price at v7 default ($/MWh) | B17: =Inputs!$B$19 -> 60 | C17: =Inputs!$B$19 -> 60 | D17: =Inputs!$B$19 -> 60 | E17: Reference: the flat $60 the v7 sweep tables in Results were generated with.
A18: Notes: (1) Model finds ITC > PTC for all three configurations at these parameters: for geothermal this contradicts Framework 2.3.5's
A19: expectation; sensitive to the omitted PTC inflation adjustment and the 7% discount on the PTC stream. (2) Geothermal faces no near-term
A20: OBBBA deadline (phaseout from 2034), so the 0% ITC scenario is a stress test rather than a live policy risk for that configuration.

Sheet Capitalization
A1: Capitalization: debt = MIN(DSCR-sized, max leverage x capital); tax equity sized to ITC/PTC + MACRS shield
B3: Solar Base | C3: Solar Coloc | D3: Wind Base | E3: Wind Coloc | F3: Geo Base | G3: Geo Coloc
A4: Total capital required ($mm) | B4: =Configurations!$B$9 -> 197 | C4: =Configurations!$B$9+Configurations!$B$11 -> 209 | D4: =Configurations!$C$9 -> 321.4 | E4: =Configurations!$C$9+Configurations!$C$11 -> 339.4 | F4: =Configurations!$D$9 -> 568.25 | G4: =Configurations!$D$9+Configurations!$D$11 -> 580.25
A5: First grid-year net energy (MWh) | B5: =Configurations!$B$4*Configurations!$B$5*8760*Configurations!$B$7*(1-Configurations!$B$8) -> 230179.95 | C5: =Configurations!$B$4*Configurations!$B$5*8760*Configurations!$B$7*(1-Configurations!$B$8) -> 230179.95 | D5: =Configurations!$C$4*Configurations!$C$5*8760*Configurations!$C$7*(1-Configurations!$C$8) -> 430466.4 | E5: =Configurations!$C$4*Configurations!$C$5*8760*Configurations!$C$7*(1-Configurations!$C$8) -> 430466.4 | F5: =Configurations!$D$4*Configurations!$D$5*8760*Configurations!$D$7*(1-Configurations!$D$8) -> 730255.5 | G5: =Configurations!$D$4*Configurations!$D$5*8760*Configurations!$D$7*(1-Configurations!$D$8) -> 730255.5
A6: First grid-year revenue ($mm) | B6: =B5*Inputs!$B$18/1000000 -> 16.572956 | C6: =C5*Inputs!$B$18/1000000 -> 16.572956 | D6: =D5*Inputs!$B$18/1000000 -> 30.993581 | E6: =E5*Inputs!$B$18/1000000 -> 30.993581 | F6: =F5*Inputs!$B$18/1000000 -> 52.578396 | G6: =G5*Inputs!$B$18/1000000 -> 52.578396
A7: First grid-year OPEX ($mm) | B7: =Configurations!$B$12+Configurations!$B$13+Inputs!$B$20*B6 -> 4.3365943 | C7: =Configurations!$B$12+Configurations!$B$13+Configurations!$B$14+Inputs!$B$20*C6 -> 5.0865943 | D7: =Configurations!$C$12+Configurations!$C$13+Inputs!$B$20*D6 -> 8.4259037 | E7: =Configurations!$C$12+Configurations!$C$13+Configurations!$C$14+Inputs!$B$20*E6 -> 9.5509037 | F7: =Configurations!$D$12+Configurations!$D$13+Inputs!$B$20*F6 -> 7.9866759 | G7: =Configurations!$D$12+Configurations!$D$13+Configurations!$D$14+Inputs!$B$20*G6 -> 8.7366759
A8: First grid-year EBITDA ($mm) | B8: =B6-B7 -> 12.236362 | C8: =C6-C7 -> 11.486362 | D8: =D6-D7 -> 22.567677 | E8: =E6-E7 -> 21.442677 | F8: =F6-F7 -> 44.59172 | G8: =G6-G7 -> 43.84172
A9: Max debt service @ DSCR ($mm/yr) | B9: =B8/Inputs!$B$13 -> 9.0639719 | C9: =C8/Inputs!$B$13 -> 8.5084163 | D9: =D8/Inputs!$B$13 -> 16.716798 | E9: =E8/Inputs!$B$13 -> 15.883465 | F9: =F8/Inputs!$B$13 -> 33.030904 | G9: =G8/Inputs!$B$13 -> 32.475348
A10: DSCR-sized debt ($mm) | B10: =B9*(1-(1+Inputs!$B$11)^-Inputs!$B$12)/Inputs!$B$11 -> 108.31793 | C10: =C9*(1-(1+Inputs!$B$11)^-Inputs!$B$12)/Inputs!$B$11 -> 101.67883 | D10: =D9*(1-(1+Inputs!$B$11)^-Inputs!$B$12)/Inputs!$B$11 -> 199.77213 | E10: =E9*(1-(1+Inputs!$B$11)^-Inputs!$B$12)/Inputs!$B$11 -> 189.81348 | F10: =F9*(1-(1+Inputs!$B$11)^-Inputs!$B$12)/Inputs!$B$11 -> 394.73193 | G10: =G9*(1-(1+Inputs!$B$11)^-Inputs!$B$12)/Inputs!$B$11 -> 388.09283
A11: Senior debt after leverage cap ($mm) | B11: =MIN(B10,Inputs!$B$14*B4) -> 108.31793 | C11: =MIN(C10,Inputs!$B$14*C4) -> 101.67883 | D11: =MIN(D10,Inputs!$B$14*D4) -> 176.77 | E11: =MIN(E10,Inputs!$B$14*E4) -> 186.67 | F11: =MIN(F10,Inputs!$B$14*F4) -> 312.5375 | G11: =MIN(G10,Inputs!$B$14*G4) -> 319.1375
A12: Actual debt service ($mm/yr) | B12: =B11/((1-(1+Inputs!$B$11)^-Inputs!$B$12)/Inputs!$B$11) -> 9.0639719 | C12: =C11/((1-(1+Inputs!$B$11)^-Inputs!$B$12)/Inputs!$B$11) -> 8.5084163 | D12: =D11/((1-(1+Inputs!$B$11)^-Inputs!$B$12)/Inputs!$B$11) -> 14.791995 | E12: =E11/((1-(1+Inputs!$B$11)^-Inputs!$B$12)/Inputs!$B$11) -> 15.620421 | F12: =F11/((1-(1+Inputs!$B$11)^-Inputs!$B$12)/Inputs!$B$11) -> 26.152929 | G12: =G11/((1-(1+Inputs!$B$11)^-Inputs!$B$12)/Inputs!$B$11) -> 26.705212
A13: ITC amount ($mm) | B13: =IF(Inputs!$B$7=1,Configurations!$B$10*Inputs!$B$6,0) -> 54 | C13: =IF(Inputs!$B$7=1,Configurations!$B$10*Inputs!$B$6,0) -> 54 | D13: =IF(Inputs!$B$7=1,Configurations!$C$10*Inputs!$B$6,0) -> 88.875 | E13: =IF(Inputs!$B$7=1,Configurations!$C$10*Inputs!$B$6,0) -> 88.875 | F13: =IF(Inputs!$B$7=1,Configurations!$D$10*Inputs!$B$6,0) -> 159.375 | G13: =IF(Inputs!$B$7=1,Configurations!$D$10*Inputs!$B$6,0) -> 159.375
A14: PTC start year (calendar) | B14: =Inputs!$B$21+Inputs!$B$5+1 -> 7 | C14: =Inputs!$B$21+1 -> 3 | D14: =Inputs!$B$21+Inputs!$B$5+1 -> 7 | E14: =Inputs!$B$21+1 -> 3 | F14: =Inputs!$B$21+Inputs!$B$5+1 -> 7 | G14: =Inputs!$B$21+1 -> 3
A15: PTC stream PV ($mm) | B15: =IF(Inputs!$B$7=2,B5*Inputs!$B$9/1000000*(1-(1+Inputs!$B$17)^-10)/Inputs!$B$17/(1+Inputs!$B$17)^(B14-1),0) -> 0 | C15: =IF(Inputs!$B$7=2,C5*Inputs!$B$9/1000000*(1-(1+Inputs!$B$17)^-10)/Inputs!$B$17/(1+Inputs!$B$17)^(C14-1),0) -> 0 | D15: =IF(Inputs!$B$7=2,D5*Inputs!$B$9/1000000*(1-(1+Inputs!$B$17)^-10)/Inputs!$B$17/(1+Inputs!$B$17)^(D14-1),0) -> 0 | E15: =IF(Inputs!$B$7=2,E5*Inputs!$B$9/1000000*(1-(1+Inputs!$B$17)^-10)/Inputs!$B$17/(1+Inputs!$B$17)^(E14-1),0) -> 0 | F15: =IF(Inputs!$B$7=2,F5*Inputs!$B$9/1000000*(1-(1+Inputs!$B$17)^-10)/Inputs!$B$17/(1+Inputs!$B$17)^(F14-1),0) -> 0 | G15: =IF(Inputs!$B$7=2,G5*Inputs!$B$9/1000000*(1-(1+Inputs!$B$17)^-10)/Inputs!$B$17/(1+Inputs!$B$17)^(G14-1),0) -> 0
A16: Depreciable basis ($mm) | B16: =IF(Inputs!$B$7=1,Configurations!$B$10-0.5*B13,Configurations!$B$10) -> 153 | C16: =IF(Inputs!$B$7=1,Configurations!$B$10-0.5*C13,Configurations!$B$10) -> 153 | D16: =IF(Inputs!$B$7=1,Configurations!$C$10-0.5*D13,Configurations!$C$10) -> 251.8125 | E16: =IF(Inputs!$B$7=1,Configurations!$C$10-0.5*E13,Configurations!$C$10) -> 251.8125 | F16: =IF(Inputs!$B$7=1,Configurations!$D$10-0.5*F13,Configurations!$D$10) -> 451.5625 | G16: =IF(Inputs!$B$7=1,Configurations!$D$10-0.5*G13,Configurations!$D$10) -> 451.5625
A17: MACRS shield PV ($mm) | B17: =SUMPRODUCT($B$25:$B$30,B16*Inputs!$B$15/(1+Inputs!$B$17)^ROW(INDIRECT("1:6"))) -> 37.964505 | C17: =SUMPRODUCT($B$25:$B$30,C16*Inputs!$B$15/(1+Inputs!$B$17)^ROW(INDIRECT("1:6"))) -> 37.964505 | D17: =SUMPRODUCT($B$25:$B$30,D16*Inputs!$B$15/(1+Inputs!$B$17)^ROW(INDIRECT("1:6"))) -> 62.483248 | E17: =SUMPRODUCT($B$25:$B$30,E16*Inputs!$B$15/(1+Inputs!$B$17)^ROW(INDIRECT("1:6"))) -> 62.483248 | F17: =SUMPRODUCT($B$25:$B$30,F16*Inputs!$B$15/(1+Inputs!$B$17)^ROW(INDIRECT("1:6"))) -> 112.04802 | G17: =SUMPRODUCT($B$25:$B$30,G16*Inputs!$B$15/(1+Inputs!$B$17)^ROW(INDIRECT("1:6"))) -> 112.04802
A18: Tax equity contribution ($mm) | B18: =IF(Inputs!$B$6=0,0,Inputs!$B$16*(B13+B15+B17)) -> 73.571604 | C18: =IF(Inputs!$B$6=0,0,Inputs!$B$16*(C13+C15+C17)) -> 73.571604 | D18: =IF(Inputs!$B$6=0,0,Inputs!$B$16*(D13+D15+D17)) -> 121.0866 | E18: =IF(Inputs!$B$6=0,0,Inputs!$B$16*(E13+E15+E17)) -> 121.0866 | F18: =IF(Inputs!$B$6=0,0,Inputs!$B$16*(F13+F15+F17)) -> 217.13841 | G18: =IF(Inputs!$B$6=0,0,Inputs!$B$16*(G13+G15+G17)) -> 217.13841
A19: Developer equity ($mm) | B19: =B4-B11-B18 -> 15.110465 | C19: =C4-C11-C18 -> 33.749566 | D19: =D4-D11-D18 -> 23.543402 | E19: =E4-E11-E18 -> 31.643402 | F19: =F4-F11-F18 -> 38.574086 | G19: =G4-G11-G18 -> 43.974086
A21: PTC start assumption: baseline is not placed in service while idle (PTC begins at COD); co-location BTM operation is assumed
A22: to qualify as placed in service (PTC begins at mechanical completion). Open tax question: validate in practitioner interviews.
A24: MACRS 5-yr schedule (Framework 2.3.3)
A25: Year 1 | B25: 0.2
A26: Year 2 | B26: 0.32
A27: Year 3 | B27: 0.192
A28: Year 4 | B28: 0.1152
A29: Year 5 | B29: 0.1152
A30: Year 6 | B30: 0.0576

Sheet SolarBase
A1: SolarBase: annual cash flow waterfall ($mm)
A2: Developer levered IRR: | B2: =IRR(K5:K37) -> 0.040713705 | C2: Unlevered (project) IRR: | D2: =IRR(M5:M37) -> 0.0091238666 | E2: NPV of dev cash @ discount rate ($mm): | F2: =K5+NPV(Inputs!$B$24,K6:K37) -> -15.39658
A4: Year | B4: Phase | C4: Op yr | D4: Net energy (MWh) | E4: Revenue | F4: OPEX | G4: EBITDA | H4: Debt service | I4: Distributable cash | J4: Dev share | K4: Dev cash flow | L4: DSCR | M4: Project CF (unlevered)
A5: 0 | B5: =IF(A5=0,"Equity",IF(A5<=Inputs!$B$21,"Construction",IF(A5<=Inputs!$B$21+Inputs!$B$5,"Queue wait",IF(A5<=Inputs!$B$21+Configurations!$B$15,"Grid ops"," ")))) -> Equity | C5: =IF(A5<=Inputs!$B$21,"",A5-Inputs!$B$21-1) | D5: =IF(OR(A5<=Inputs!$B$21,A5>Inputs!$B$21+Configurations!$B$15),0,Configurations!$B$4*Configurations!$B$5*8760*(1-Configurations!$B$6)^C5*Configurations!$B$7*(1-Configurations!$B$8)) -> 0 | E5: =IF(OR(A5<=Inputs!$B$21,A5>Inputs!$B$21+Configurations!$B$15),0,IF(A5<=Inputs!$B$21+Inputs!$B$5,0,D5*Inputs!$B$18/1000000)) -> 0 | F5: =IF(OR(A5<=Inputs!$B$21,A5>Inputs!$B$21+Configurations!$B$15),0,IF(A5<=Inputs!$B$21+Inputs!$B$5,Configurations!$B$13,Configurations!$B$12+Configurations!$B$13+Inputs!$B$20*E5)) -> 0 | G5: =E5-F5 -> 0 | H5: =IF(AND(A5>Inputs!$B$21,A5<=Inputs!$B$21+Inputs!$B$12),Capitalization!B$12,0) -> 0 | I5: =G5-H5 -> 0 | J5: =IF(A5<=Inputs!$B$21,"",IF(AND(A5<=Inputs!$B$22,Capitalization!B$18>0),Inputs!$B$25,Inputs!$B$26)) | K5: =IF(A5=0,-Capitalization!B$19,IF(A5<=Inputs!$B$21,0,I5*J5-IF(AND(A5=Inputs!$B$22,Capitalization!B$18>0),Inputs!$B$23,0))) -> -15.110465 | L5: =IF(H5>0,G5/H5,"") | M5: =IF(A5=0,-Capitalization!B$4,IF(A5<=Inputs!$B$21,0,G5)) -> -197
A6: 1 | B6: =IF(A6=0,"Equity",IF(A6<=Inputs!$B$21,"Construction",IF(A6<=Inputs!$B$21+Inputs!$B$5,"Queue wait",IF(A6<=Inputs!$B$21+Configurations!$B$15,"Grid ops"," ")))) -> Construction | C6: =IF(A6<=Inputs!$B$21,"",A6-Inputs!$B$21-1) | D6: =IF(OR(A6<=Inputs!$B$21,A6>Inputs!$B$21+Configurations!$B$15),0,Configurations!$B$4*Configurations!$B$5*8760*(1-Configurations!$B$6)^C6*Configurations!$B$7*(1-Configurations!$B$8)) -> 0 | E6: =IF(OR(A6<=Inputs!$B$21,A6>Inputs!$B$21+Configurations!$B$15),0,IF(A6<=Inputs!$B$21+Inputs!$B$5,0,D6*Inputs!$B$18/1000000)) -> 0 | F6: =IF(OR(A6<=Inputs!$B$21,A6>Inputs!$B$21+Configurations!$B$15),0,IF(A6<=Inputs!$B$21+Inputs!$B$5,Configurations!$B$13,Configurations!$B$12+Configurations!$B$13+Inputs!$B$20*E6)) -> 0 | G6: =E6-F6 -> 0 | H6: =IF(AND(A6>Inputs!$B$21,A6<=Inputs!$B$21+Inputs!$B$12),Capitalization!B$12,0) -> 0 | I6: =G6-H6 -> 0 | J6: =IF(A6<=Inputs!$B$21,"",IF(AND(A6<=Inputs!$B$22,Capitalization!B$18>0),Inputs!$B$25,Inputs!$B$26)) | K6: =IF(A6=0,-Capitalization!B$19,IF(A6<=Inputs!$B$21,0,I6*J6-IF(AND(A6=Inputs!$B$22,Capitalization!B$18>0),Inputs!$B$23,0))) -> 0 | L6: =IF(H6>0,G6/H6,"") | M6: =IF(A6=0,-Capitalization!B$4,IF(A6<=Inputs!$B$21,0,G6)) -> 0
A7: 2 | B7: =IF(A7=0,"Equity",IF(A7<=Inputs!$B$21,"Construction",IF(A7<=Inputs!$B$21+Inputs!$B$5,"Queue wait",IF(A7<=Inputs!$B$21+Configurations!$B$15,"Grid ops"," ")))) -> Construction | C7: =IF(A7<=Inputs!$B$21,"",A7-Inputs!$B$21-1) | D7: =IF(OR(A7<=Inputs!$B$21,A7>Inputs!$B$21+Configurations!$B$15),0,Configurations!$B$4*Configurations!$B$5*8760*(1-Configurations!$B$6)^C7*Configurations!$B$7*(1-Configurations!$B$8)) -> 0 | E7: =IF(OR(A7<=Inputs!$B$21,A7>Inputs!$B$21+Configurations!$B$15),0,IF(A7<=Inputs!$B$21+Inputs!$B$5,0,D7*Inputs!$B$18/1000000)) -> 0 | F7: =IF(OR(A7<=Inputs!$B$21,A7>Inputs!$B$21+Configurations!$B$15),0,IF(A7<=Inputs!$B$21+Inputs!$B$5,Configurations!$B$13,Configurations!$B$12+Configurations!$B$13+Inputs!$B$20*E7)) -> 0 | G7: =E7-F7 -> 0 | H7: =IF(AND(A7>Inputs!$B$21,A7<=Inputs!$B$21+Inputs!$B$12),Capitalization!B$12,0) -> 0 | I7: =G7-H7 -> 0 | J7: =IF(A7<=Inputs!$B$21,"",IF(AND(A7<=Inputs!$B$22,Capitalization!B$18>0),Inputs!$B$25,Inputs!$B$26)) | K7: =IF(A7=0,-Capitalization!B$19,IF(A7<=Inputs!$B$21,0,I7*J7-IF(AND(A7=Inputs!$B$22,Capitalization!B$18>0),Inputs!$B$23,0))) -> 0 | L7: =IF(H7>0,G7/H7,"") | M7: =IF(A7=0,-Capitalization!B$4,IF(A7<=Inputs!$B$21,0,G7)) -> 0
A8: 3 | B8: =IF(A8=0,"Equity",IF(A8<=Inputs!$B$21,"Construction",IF(A8<=Inputs!$B$21+Inputs!$B$5,"Queue wait",IF(A8<=Inputs!$B$21+Configurations!$B$15,"Grid ops"," ")))) -> Queue wait | C8: =IF(A8<=Inputs!$B$21,"",A8-Inputs!$B$21-1) -> 0 | D8: =IF(OR(A8<=Inputs!$B$21,A8>Inputs!$B$21+Configurations!$B$15),0,Configurations!$B$4*Configurations!$B$5*8760*(1-Configurations!$B$6)^C8*Configurations!$B$7*(1-Configurations!$B$8)) -> 230179.95 | E8: =IF(OR(A8<=Inputs!$B$21,A8>Inputs!$B$21+Configurations!$B$15),0,IF(A8<=Inputs!$B$21+Inputs!$B$5,0,D8*Inputs!$B$18/1000000)) -> 0 | F8: =IF(OR(A8<=Inputs!$B$21,A8>Inputs!$B$21+Configurations!$B$15),0,IF(A8<=Inputs!$B$21+Inputs!$B$5,Configurations!$B$13,Configurations!$B$12+Configurations!$B$13+Inputs!$B$20*E8)) -> 1.088 | G8: =E8-F8 -> -1.088 | H8: =IF(AND(A8>Inputs!$B$21,A8<=Inputs!$B$21+Inputs!$B$12),Capitalization!B$12,0) -> 9.0639719 | I8: =G8-H8 -> -10.151972 | J8: =IF(A8<=Inputs!$B$21,"",IF(AND(A8<=Inputs!$B$22,Capitalization!B$18>0),Inputs!$B$25,Inputs!$B$26)) -> 0.7 | K8: =IF(A8=0,-Capitalization!B$19,IF(A8<=Inputs!$B$21,0,I8*J8-IF(AND(A8=Inputs!$B$22,Capitalization!B$18>0),Inputs!$B$23,0))) -> -7.1063803 | L8: =IF(H8>0,G8/H8,"") -> -0.12003568 | M8: =IF(A8=0,-Capitalization!B$4,IF(A8<=Inputs!$B$21,0,G8)) -> -1.088
A9: 4 | B9: =IF(A9=0,"Equity",IF(A9<=Inputs!$B$21,"Construction",IF(A9<=Inputs!$B$21+Inputs!$B$5,"Queue wait",IF(A9<=Inputs!$B$21+Configurations!$B$15,"Grid ops"," ")))) -> Queue wait | C9: =IF(A9<=Inputs!$B$21,"",A9-Inputs!$B$21-1) -> 1 | D9: =IF(OR(A9<=Inputs!$B$21,A9>Inputs!$B$21+Configurations!$B$15),0,Configurations!$B$4*Configurations!$B$5*8760*(1-Configurations!$B$6)^C9*Configurations!$B$7*(1-Configurations!$B$8)) -> 229029.05 | E9: =IF(OR(A9<=Inputs!$B$21,A9>Inputs!$B$21+Configurations!$B$15),0,IF(A9<=Inputs!$B$21+Inputs!$B$5,0,D9*Inputs!$B$18/1000000)) -> 0 | F9: =IF(OR(A9<=Inputs!$B$21,A9>Inputs!$B$21+Configurations!$B$15),0,IF(A9<=Inputs!$B$21+Inputs!$B$5,Configurations!$B$13,Configurations!$B$12+Configurations!$B$13+Inputs!$B$20*E9)) -> 1.088 | G9: =E9-F9 -> -1.088 | H9: =IF(AND(A9>Inputs!$B$21,A9<=Inputs!$B$21+Inputs!$B$12),Capitalization!B$12,0) -> 9.0639719 | I9: =G9-H9 -> -10.151972 | J9: =IF(A9<=Inputs!$B$21,"",IF(AND(A9<=Inputs!$B$22,Capitalization!B$18>0),Inputs!$B$25,Inputs!$B$26)) -> 0.7 | K9: =IF(A9=0,-Capitalization!B$19,IF(A9<=Inputs!$B$21,0,I9*J9-IF(AND(A9=Inputs!$B$22,Capitalization!B$18>0),Inputs!$B$23,0))) -> -7.1063803 | L9: =IF(H9>0,G9/H9,"") -> -0.12003568 | M9: =IF(A9=0,-Capitalization!B$4,IF(A9<=Inputs!$B$21,0,G9)) -> -1.088
A10: 5 | B10: =IF(A10=0,"Equity",IF(A10<=Inputs!$B$21,"Construction",IF(A10<=Inputs!$B$21+Inputs!$B$5,"Queue wait",IF(A10<=Inputs!$B$21+Configurations!$B$15,"Grid ops"," ")))) -> Queue wait | C10: =IF(A10<=Inputs!$B$21,"",A10-Inputs!$B$21-1) -> 2 | D10: =IF(OR(A10<=Inputs!$B$21,A10>Inputs!$B$21+Configurations!$B$15),0,Configurations!$B$4*Configurations!$B$5*8760*(1-Configurations!$B$6)^C10*Configurations!$B$7*(1-Configurations!$B$8)) -> 227883.9 | E10: =IF(OR(A10<=Inputs!$B$21,A10>Inputs!$B$21+Configurations!$B$15),0,IF(A10<=Inputs!$B$21+Inputs!$B$5,0,D10*Inputs!$B$18/1000000)) -> 0 | F10: =IF(OR(A10<=Inputs!$B$21,A10>Inputs!$B$21+Configurations!$B$15),0,IF(A10<=Inputs!$B$21+Inputs!$B$5,Configurations!$B$13,Configurations!$B$12+Configurations!$B$13+Inputs!$B$20*E10)) -> 1.088 | G10: =E10-F10 -> -1.088 | H10: =IF(AND(A10>Inputs!$B$21,A10<=Inputs!$B$21+Inputs!$B$12),Capitalization!B$12,0) -> 9.0639719 | I10: =G10-H10 -> -10.151972 | J10: =IF(A10<=Inputs!$B$21,"",IF(AND(A10<=Inputs!$B$22,Capitalization!B$18>0),Inputs!$B$25,Inputs!$B$26)) -> 0.7 | K10: =IF(A10=0,-Capitalization!B$19,IF(A10<=Inputs!$B$21,0,I10*J10-IF(AND(A10=Inputs!$B$22,Capitalization!B$18>0),Inputs!$B$23,0))) -> -7.1063803 | L10: =IF(H10>0,G10/H10,"") -> -0.12003568 | M10: =IF(A10=0,-Capitalization!B$4,IF(A10<=Inputs!$B$21,0,G10)) -> -1.088
A11: 6 | B11: =IF(A11=0,"Equity",IF(A11<=Inputs!$B$21,"Construction",IF(A11<=Inputs!$B$21+Inputs!$B$5,"Queue wait",IF(A11<=Inputs!$B$21+Configurations!$B$15,"Grid ops"," ")))) -> Queue wait | C11: =IF(A11<=Inputs!$B$21,"",A11-Inputs!$B$21-1) -> 3 | D11: =IF(OR(A11<=Inputs!$B$21,A11>Inputs!$B$21+Configurations!$B$15),0,Configurations!$B$4*Configurations!$B$5*8760*(1-Configurations!$B$6)^C11*Configurations!$B$7*(1-Configurations!$B$8)) -> 226744.49 | E11: =IF(OR(A11<=Inputs!$B$21,A11>Inputs!$B$21+Configurations!$B$15),0,IF(A11<=Inputs!$B$21+Inputs!$B$5,0,D11*Inputs!$B$18/1000000)) -> 0 | F11: =IF(OR(A11<=Inputs!$B$21,A11>Inputs!$B$21+Configurations!$B$15),0,IF(A11<=Inputs!$B$21+Inputs!$B$5,Configurations!$B$13,Configurations!$B$12+Configurations!$B$13+Inputs!$B$20*E11)) -> 1.088 | G11: =E11-F11 -> -1.088 | H11: =IF(AND(A11>Inputs!$B$21,A11<=Inputs!$B$21+Inputs!$B$12),Capitalization!B$12,0) -> 9.0639719 | I11: =G11-H11 -> -10.151972 | J11: =IF(A11<=Inputs!$B$21,"",IF(AND(A11<=Inputs!$B$22,Capitalization!B$18>0),Inputs!$B$25,Inputs!$B$26)) -> 0.7 | K11: =IF(A11=0,-Capitalization!B$19,IF(A11<=Inputs!$B$21,0,I11*J11-IF(AND(A11=Inputs!$B$22,Capitalization!B$18>0),Inputs!$B$23,0))) -> -8.1063803 | L11: =IF(H11>0,G11/H11,"") -> -0.12003568 | M11: =IF(A11=0,-Capitalization!B$4,IF(A11<=Inputs!$B$21,0,G11)) -> -1.088
A12: 7 | B12: =IF(A12=0,"Equity",IF(A12<=Inputs!$B$21,"Construction",IF(A12<=Inputs!$B$21+Inputs!$B$5,"Queue wait",IF(A12<=Inputs!$B$21+Configurations!$B$15,"Grid ops"," ")))) -> Grid ops | C12: =IF(A12<=Inputs!$B$21,"",A12-Inputs!$B$21-1) -> 4 | D12: =IF(OR(A12<=Inputs!$B$21,A12>Inputs!$B$21+Configurations!$B$15),0,Configurations!$B$4*Configurations!$B$5*8760*(1-Configurations!$B$6)^C12*Configurations!$B$7*(1-Configurations!$B$8)) -> 225610.76 | E12: =IF(OR(A12<=Inputs!$B$21,A12>Inputs!$B$21+Configurations!$B$15),0,IF(A12<=Inputs!$B$21+Inputs!$B$5,0,D12*Inputs!$B$18/1000000)) -> 16.243975 | F12: =IF(OR(A12<=Inputs!$B$21,A12>Inputs!$B$21+Configurations!$B$15),0,IF(A12<=Inputs!$B$21+Inputs!$B$5,Configurations!$B$13,Configurations!$B$12+Configurations!$B$13+Inputs!$B$20*E12)) -> 4.3316596 | G12: =E12-F12 -> 11.912315 | H12: =IF(AND(A12>Inputs!$B$21,A12<=Inputs!$B$21+Inputs!$B$12),Capitalization!B$12,0) -> 9.0639719 | I12: =G12-H12 -> 2.8483434 | J12: =IF(A12<=Inputs!$B$21,"",IF(AND(A12<=Inputs!$B$22,Capitalization!B$18>0),Inputs!$B$25,Inputs!$B$26)) -> 0.975 | K12: =IF(A12=0,-Capitalization!B$19,IF(A12<=Inputs!$B$21,0,I12*J12-IF(AND(A12=Inputs!$B$22,Capitalization!B$18>0),Inputs!$B$23,0))) -> 2.7771348 | L12: =IF(H12>0,G12/H12,"") -> 1.3142489 | M12: =IF(A12=0,-Capitalization!B$4,IF(A12<=Inputs!$B$21,0,G12)) -> 11.912315
A13: 8 | B13: =IF(A13=0,"Equity",IF(A13<=Inputs!$B$21,"Construction",IF(A13<=Inputs!$B$21+Inputs!$B$5,"Queue wait",IF(A13<=Inputs!$B$21+Configurations!$B$15,"Grid ops"," ")))) -> Grid ops | C13: =IF(A13<=Inputs!$B$21,"",A13-Inputs!$B$21-1) -> 5 | D13: =IF(OR(A13<=Inputs!$B$21,A13>Inputs!$B$21+Configurations!$B$15),0,Configurations!$B$4*Configurations!$B$5*8760*(1-Configurations!$B$6)^C13*Configurations!$B$7*(1-Configurations!$B$8)) -> 224482.71 | E13: =IF(OR(A13<=Inputs!$B$21,A13>Inputs!$B$21+Configurations!$B$15),0,IF(A13<=Inputs!$B$21+Inputs!$B$5,0,D13*Inputs!$B$18/1000000)) -> 16.162755 | F13: =IF(OR(A13<=Inputs!$B$21,A13>Inputs!$B$21+Configurations!$B$15),0,IF(A13<=Inputs!$B$21+Inputs!$B$5,Configurations!$B$13,Configurations!$B$12+Configurations!$B$13+Inputs!$B$20*E13)) -> 4.3304413 | G13: =E13-F13 -> 11.832314 | H13: =IF(AND(A13>Inputs!$B$21,A13<=Inputs!$B$21+Inputs!$B$12),Capitalization!B$12,0) -> 9.0639719 | I13: =G13-H13 -> 2.7683418 | J13: =IF(A13<=Inputs!$B$21,"",IF(AND(A13<=Inputs!$B$22,Capitalization!B$18>0),Inputs!$B$25,Inputs!$B$26)) -> 0.975 | K13: =IF(A13=0,-Capitalization!B$19,IF(A13<=Inputs!$B$21,0,I13*J13-IF(AND(A13=Inputs!$B$22,Capitalization!B$18>0),Inputs!$B$23,0))) -> 2.6991333 | L13: =IF(H13>0,G13/H13,"") -> 1.3054226 | M13: =IF(A13=0,-Capitalization!B$4,IF(A13<=Inputs!$B$21,0,G13)) -> 11.832314
A14: 9 | B14: =IF(A14=0,"Equity",IF(A14<=Inputs!$B$21,"Construction",IF(A14<=Inputs!$B$21+Inputs!$B$5,"Queue wait",IF(A14<=Inputs!$B$21+Configurations!$B$15,"Grid ops"," ")))) -> Grid ops | C14: =IF(A14<=Inputs!$B$21,"",A14-Inputs!$B$21-1) -> 6 | D14: =IF(OR(A14<=Inputs!$B$21,A14>Inputs!$B$21+Configurations!$B$15),0,Configurations!$B$4*Configurations!$B$5*8760*(1-Configurations!$B$6)^C14*Configurations!$B$7*(1-Configurations!$B$8)) -> 223360.3 | E14: =IF(OR(A14<=Inputs!$B$21,A14>Inputs!$B$21+Configurations!$B$15),0,IF(A14<=Inputs!$B$21+Inputs!$B$5,0,D14*Inputs!$B$18/1000000)) -> 16.081941 | F14: =IF(OR(A14<=Inputs!$B$21,A14>Inputs!$B$21+Configurations!$B$15),0,IF(A14<=Inputs!$B$21+Inputs!$B$5,Configurations!$B$13,Configurations!$B$12+Configurations!$B$13+Inputs!$B$20*E14)) -> 4.3292291 | G14: =E14-F14 -> 11.752712 | H14: =IF(AND(A14>Inputs!$B$21,A14<=Inputs!$B$21+Inputs!$B$12),Capitalization!B$12,0) -> 9.0639719 | I14: =G14-H14 -> 2.6887403 | J14: =IF(A14<=Inputs!$B$21,"",IF(AND(A14<=Inputs!$B$22,Capitalization!B$18>0),Inputs!$B$25,Inputs!$B$26)) -> 0.975 | K14: =IF(A14=0,-Capitalization!B$19,IF(A14<=Inputs!$B$21,0,I14*J14-IF(AND(A14=Inputs!$B$22,Capitalization!B$18>0),Inputs!$B$23,0))) -> 2.6215218 | L14: =IF(H14>0,G14/H14,"") -> 1.2966404 | M14: =IF(A14=0,-Capitalization!B$4,IF(A14<=Inputs!$B$21,0,G14)) -> 11.752712
A15: 10 | B15: =IF(A15=0,"Equity",IF(A15<=Inputs!$B$21,"Construction",IF(A15<=Inputs!$B$21+Inputs!$B$5,"Queue wait",IF(A15<=Inputs!$B$21+Configurations!$B$15,"Grid ops"," ")))) -> Grid ops | C15: =IF(A15<=Inputs!$B$21,"",A15-Inputs!$B$21-1) -> 7 | D15: =IF(OR(A15<=Inputs!$B$21,A15>Inputs!$B$21+Configurations!$B$15),0,Configurations!$B$4*Configurations!$B$5*8760*(1-Configurations!$B$6)^C15*Configurations!$B$7*(1-Configurations!$B$8)) -> 222243.49 | E15: =IF(OR(A15<=Inputs!$B$21,A15>Inputs!$B$21+Configurations!$B$15),0,IF(A15<=Inputs!$B$21+Inputs!$B$5,0,D15*Inputs!$B$18/1000000)) -> 16.001532 | F15: =IF(OR(A15<=Inputs!$B$21,A15>Inputs!$B$21+Configurations!$B$15),0,IF(A15<=Inputs!$B$21+Inputs!$B$5,Configurations!$B$13,Configurations!$B$12+Configurations!$B$13+Inputs!$B$20*E15)) -> 4.328023 | G15: =E15-F15 -> 11.673509 | H15: =IF(AND(A15>Inputs!$B$21,A15<=Inputs!$B$21+Inputs!$B$12),Capitalization!B$12,0) -> 9.0639719 | I15: =G15-H15 -> 2.6095367 | J15: =IF(A15<=Inputs!$B$21,"",IF(AND(A15<=Inputs!$B$22,Capitalization!B$18>0),Inputs!$B$25,Inputs!$B$26)) -> 0.975 | K15: =IF(A15=0,-Capitalization!B$19,IF(A15<=Inputs!$B$21,0,I15*J15-IF(AND(A15=Inputs!$B$22,Capitalization!B$18>0),Inputs!$B$23,0))) -> 2.5442983 | L15: =IF(H15>0,G15/H15,"") -> 1.2879021 | M15: =IF(A15=0,-Capitalization!B$4,IF(A15<=Inputs!$B$21,0,G15)) -> 11.673509
A16: 11 | B16: =IF(A16=0,"Equity",IF(A16<=Inputs!$B$21,"Construction",IF(A16<=Inputs!$B$21+Inputs!$B$5,"Queue wait",IF(A16<=Inputs!$B$21+Configurations!$B$15,"Grid ops"," ")))) -> Grid ops | C16: =IF(A16<=Inputs!$B$21,"",A16-Inputs!$B$21-1) -> 8 | D16: =IF(OR(A16<=Inputs!$B$21,A16>Inputs!$B$21+Configurations!$B$15),0,Configurations!$B$4*Configurations!$B$5*8760*(1-Configurations!$B$6)^C16*Configurations!$B$7*(1-Configurations!$B$8)) -> 221132.28 | E16: =IF(OR(A16<=Inputs!$B$21,A16>Inputs!$B$21+Configurations!$B$15),0,IF(A16<=Inputs!$B$21+Inputs!$B$5,0,D16*Inputs!$B$18/1000000)) -> 15.921524 | F16: =IF(OR(A16<=Inputs!$B$21,A16>Inputs!$B$21+Configurations!$B$15),0,IF(A16<=Inputs!$B$21+Inputs!$B$5,Configurations!$B$13,Configurations!$B$12+Configurations!$B$13+Inputs!$B$20*E16)) -> 4.3268229 | G16: =E16-F16 -> 11.594701 | H16: =IF(AND(A16>Inputs!$B$21,A16<=Inputs!$B$21+Inputs!$B$12),Capitalization!B$12,0) -> 9.0639719 | I16: =G16-H16 -> 2.5307292 | J16: =IF(A16<=Inputs!$B$21,"",IF(AND(A16<=Inputs!$B$22,Capitalization!B$18>0),Inputs!$B$25,Inputs!$B$26)) -> 0.975 | K16: =IF(A16=0,-Capitalization!B$19,IF(A16<=Inputs!$B$21,0,I16*J16-IF(AND(A16=Inputs!$B$22,Capitalization!B$18>0),Inputs!$B$23,0))) -> 2.4674609 | L16: =IF(H16>0,G16/H16,"") -> 1.2792075 | M16: =IF(A16=0,-Capitalization!B$4,IF(A16<=Inputs!$B$21,0,G16)) -> 11.594701
... A37: 32 | B37: =IF(A37=0,"Equity",IF(A37<=Inputs!$B$21,"Construction",IF(A37<=Inputs!$B$21+Inputs!$B$5,"Queue wait",IF(A37<=Inputs!$B$21+Configurations!$B$15,"Grid ops"," ")))) | C37: =IF(A37<=Inputs!$B$21,"",A37-Inputs!$B$21-1) -> 29 | D37: =IF(OR(A37<=Inputs!$B$21,A37>Inputs!$B$21+Configurations!$B$15),0,Configurations!$B$4*Configurations!$B$5*8760*(1-Configurations!$B$6)^C37*Configurations!$B$7*(1-Configurations!$B$8)) -> 0 | E37: =IF(OR(A37<=Inputs!$B$21,A37>Inputs!$B$21+Configurations!$B$15),0,IF(A37<=Inputs!$B$21+Inputs!$B$5,0,D37*Inputs!$B$18/1000000)) -> 0 | F37: =IF(OR(A37<=Inputs!$B$21,A37>Inputs!$B$21+Configurations!$B$15),0,IF(A37<=Inputs!$B$21+Inputs!$B$5,Configurations!$B$13,Configurations!$B$12+Configurations!$B$13+Inputs!$B$20*E37)) -> 0 | G37: =E37-F37 -> 0 | H37: =IF(AND(A37>Inputs!$B$21,A37<=Inputs!$B$21+Inputs!$B$12),Capitalization!B$12,0) -> 0 | I37: =G37-H37 -> 0 | J37: =IF(A37<=Inputs!$B$21,"",IF(AND(A37<=Inputs!$B$22,Capitalization!B$18>0),Inputs!$B$25,Inputs!$B$26)) -> 0.975 | K37: =IF(A37=0,-Capitalization!B$19,IF(A37<=Inputs!$B$21,0,I37*J37-IF(AND(A37=Inputs!$B$22,Capitalization!B$18>0),Inputs!$B$23,0))) -> 0 | L37: =IF(H37>0,G37/H37,"") | M37: =IF(A37=0,-Capitalization!B$4,IF(A37<=Inputs!$B$21,0,G37)) -> 0

Sheet SolarColoc
A1: SolarColoc: annual cash flow waterfall ($mm)
A2: Developer levered IRR: | B2: =IRR(K5:K37) -> 0.11794323 | C2: Unlevered (project) IRR: | D2: =IRR(M5:M37) -> 0.031641614 | E2: NPV of dev cash @ discount rate ($mm): | F2: =K5+NPV(Inputs!$B$24,K6:K37) -> 11.741962
A4: Year | B4: Phase | C4: Op yr | D4: Net energy (MWh) | E4: Revenue | F4: OPEX | G4: EBITDA | H4: Debt service | I4: Distributable cash | J4: Dev share | K4: Dev cash flow | L4: DSCR | M4: Project CF (unlevered)
A5: 0 | B5: =IF(A5=0,"Equity",IF(A5<=Inputs!$B$21,"Construction",IF(A5<=Inputs!$B$21+Inputs!$B$5,"Queue wait",IF(A5<=Inputs!$B$21+Configurations!$B$15,"Grid ops"," ")))) -> Equity | C5: =IF(A5<=Inputs!$B$21,"",A5-Inputs!$B$21-1) | D5: =IF(OR(A5<=Inputs!$B$21,A5>Inputs!$B$21+Configurations!$B$15),0,Configurations!$B$4*Configurations!$B$5*8760*(1-Configurations!$B$6)^C5*Configurations!$B$7*(1-Configurations!$B$8)) -> 0 | E5: =IF(OR(A5<=Inputs!$B$21,A5>Inputs!$B$21+Configurations!$B$15),0,IF(A5<=Inputs!$B$21+Inputs!$B$5,D5*(1-Inputs!$B$10)*Configurations!$B$16/1000000,D5*Inputs!$B$18/1000000)) -> 0 | F5: =IF(OR(A5<=Inputs!$B$21,A5>Inputs!$B$21+Configurations!$B$15),0,Configurations!$B$12+Configurations!$B$13+Configurations!$B$14+Inputs!$B$20*E5) -> 0 | G5: =E5-F5 -> 0 | H5: =IF(AND(A5>Inputs!$B$21,A5<=Inputs!$B$21+Inputs!$B$12),Capitalization!C$12,0) -> 0 | I5: =G5-H5 -> 0 | J5: =IF(A5<=Inputs!$B$21,"",IF(AND(A5<=Inputs!$B$22,Capitalization!C$18>0),Inputs!$B$25,Inputs!$B$26)) | K5: =IF(A5=0,-Capitalization!C$19,IF(A5<=Inputs!$B$21,0,I5*J5-IF(AND(A5=Inputs!$B$22,Capitalization!C$18>0),Inputs!$B$23,0))) -> -33.749566 | L5: =IF(H5>0,G5/H5,"") | M5: =IF(A5=0,-Capitalization!C$4,IF(A5<=Inputs!$B$21,0,G5)) -> -209
A6: 1 | B6: =IF(A6=0,"Equity",IF(A6<=Inputs!$B$21,"Construction",IF(A6<=Inputs!$B$21+Inputs!$B$5,"Queue wait",IF(A6<=Inputs!$B$21+Configurations!$B$15,"Grid ops"," ")))) -> Construction | C6: =IF(A6<=Inputs!$B$21,"",A6-Inputs!$B$21-1) | D6: =IF(OR(A6<=Inputs!$B$21,A6>Inputs!$B$21+Configurations!$B$15),0,Configurations!$B$4*Configurations!$B$5*8760*(1-Configurations!$B$6)^C6*Configurations!$B$7*(1-Configurations!$B$8)) -> 0 | E6: =IF(OR(A6<=Inputs!$B$21,A6>Inputs!$B$21+Configurations!$B$15),0,IF(A6<=Inputs!$B$21+Inputs!$B$5,D6*(1-Inputs!$B$10)*Configurations!$B$16/1000000,D6*Inputs!$B$18/1000000)) -> 0 | F6: =IF(OR(A6<=Inputs!$B$21,A6>Inputs!$B$21+Configurations!$B$15),0,Configurations!$B$12+Configurations!$B$13+Configurations!$B$14+Inputs!$B$20*E6) -> 0 | G6: =E6-F6 -> 0 | H6: =IF(AND(A6>Inputs!$B$21,A6<=Inputs!$B$21+Inputs!$B$12),Capitalization!C$12,0) -> 0 | I6: =G6-H6 -> 0 | J6: =IF(A6<=Inputs!$B$21,"",IF(AND(A6<=Inputs!$B$22,Capitalization!C$18>0),Inputs!$B$25,Inputs!$B$26)) | K6: =IF(A6=0,-Capitalization!C$19,IF(A6<=Inputs!$B$21,0,I6*J6-IF(AND(A6=Inputs!$B$22,Capitalization!C$18>0),Inputs!$B$23,0))) -> 0 | L6: =IF(H6>0,G6/H6,"") | M6: =IF(A6=0,-Capitalization!C$4,IF(A6<=Inputs!$B$21,0,G6)) -> 0
A7: 2 | B7: =IF(A7=0,"Equity",IF(A7<=Inputs!$B$21,"Construction",IF(A7<=Inputs!$B$21+Inputs!$B$5,"Queue wait",IF(A7<=Inputs!$B$21+Configurations!$B$15,"Grid ops"," ")))) -> Construction | C7: =IF(A7<=Inputs!$B$21,"",A7-Inputs!$B$21-1) | D7: =IF(OR(A7<=Inputs!$B$21,A7>Inputs!$B$21+Configurations!$B$15),0,Configurations!$B$4*Configurations!$B$5*8760*(1-Configurations!$B$6)^C7*Configurations!$B$7*(1-Configurations!$B$8)) -> 0 | E7: =IF(OR(A7<=Inputs!$B$21,A7>Inputs!$B$21+Configurations!$B$15),0,IF(A7<=Inputs!$B$21+Inputs!$B$5,D7*(1-Inputs!$B$10)*Configurations!$B$16/1000000,D7*Inputs!$B$18/1000000)) -> 0 | F7: =IF(OR(A7<=Inputs!$B$21,A7>Inputs!$B$21+Configurations!$B$15),0,Configurations!$B$12+Configurations!$B$13+Configurations!$B$14+Inputs!$B$20*E7) -> 0 | G7: =E7-F7 -> 0 | H7: =IF(AND(A7>Inputs!$B$21,A7<=Inputs!$B$21+Inputs!$B$12),Capitalization!C$12,0) -> 0 | I7: =G7-H7 -> 0 | J7: =IF(A7<=Inputs!$B$21,"",IF(AND(A7<=Inputs!$B$22,Capitalization!C$18>0),Inputs!$B$25,Inputs!$B$26)) | K7: =IF(A7=0,-Capitalization!C$19,IF(A7<=Inputs!$B$21,0,I7*J7-IF(AND(A7=Inputs!$B$22,Capitalization!C$18>0),Inputs!$B$23,0))) -> 0 | L7: =IF(H7>0,G7/H7,"") | M7: =IF(A7=0,-Capitalization!C$4,IF(A7<=Inputs!$B$21,0,G7)) -> 0
A8: 3 | B8: =IF(A8=0,"Equity",IF(A8<=Inputs!$B$21,"Construction",IF(A8<=Inputs!$B$21+Inputs!$B$5,"Queue wait",IF(A8<=Inputs!$B$21+Configurations!$B$15,"Grid ops"," ")))) -> Queue wait | C8: =IF(A8<=Inputs!$B$21,"",A8-Inputs!$B$21-1) -> 0 | D8: =IF(OR(A8<=Inputs!$B$21,A8>Inputs!$B$21+Configurations!$B$15),0,Configurations!$B$4*Configurations!$B$5*8760*(1-Configurations!$B$6)^C8*Configurations!$B$7*(1-Configurations!$B$8)) -> 230179.95 | E8: =IF(OR(A8<=Inputs!$B$21,A8>Inputs!$B$21+Configurations!$B$15),0,IF(A8<=Inputs!$B$21+Inputs!$B$5,D8*(1-Inputs!$B$10)*Configurations!$B$16/1000000,D8*Inputs!$B$18/1000000)) -> 27.631648 | F8: =IF(OR(A8<=Inputs!$B$21,A8>Inputs!$B$21+Configurations!$B$15),0,Configurations!$B$12+Configurations!$B$13+Configurations!$B$14+Inputs!$B$20*E8) -> 5.2524747 | G8: =E8-F8 -> 22.379173 | H8: =IF(AND(A8>Inputs!$B$21,A8<=Inputs!$B$21+Inputs!$B$12),Capitalization!C$12,0) -> 8.5084163 | I8: =G8-H8 -> 13.870757 | J8: =IF(A8<=Inputs!$B$21,"",IF(AND(A8<=Inputs!$B$22,Capitalization!C$18>0),Inputs!$B$25,Inputs!$B$26)) -> 0.7 | K8: =IF(A8=0,-Capitalization!C$19,IF(A8<=Inputs!$B$21,0,I8*J8-IF(AND(A8=Inputs!$B$22,Capitalization!C$18>0),Inputs!$B$23,0))) -> 9.70953 | L8: =IF(H8>0,G8/H8,"") -> 2.6302396 | M8: =IF(A8=0,-Capitalization!C$4,IF(A8<=Inputs!$B$21,0,G8)) -> 22.379173
A9: 4 | B9: =IF(A9=0,"Equity",IF(A9<=Inputs!$B$21,"Construction",IF(A9<=Inputs!$B$21+Inputs!$B$5,"Queue wait",IF(A9<=Inputs!$B$21+Configurations!$B$15,"Grid ops"," ")))) -> Queue wait | C9: =IF(A9<=Inputs!$B$21,"",A9-Inputs!$B$21-1) -> 1 | D9: =IF(OR(A9<=Inputs!$B$21,A9>Inputs!$B$21+Configurations!$B$15),0,Configurations!$B$4*Configurations!$B$5*8760*(1-Configurations!$B$6)^C9*Configurations!$B$7*(1-Configurations!$B$8)) -> 229029.05 | E9: =IF(OR(A9<=Inputs!$B$21,A9>Inputs!$B$21+Configurations!$B$15),0,IF(A9<=Inputs!$B$21+Inputs!$B$5,D9*(1-Inputs!$B$10)*Configurations!$B$16/1000000,D9*Inputs!$B$18/1000000)) -> 27.49349 | F9: =IF(OR(A9<=Inputs!$B$21,A9>Inputs!$B$21+Configurations!$B$15),0,Configurations!$B$12+Configurations!$B$13+Configurations!$B$14+Inputs!$B$20*E9) -> 5.2504023 | G9: =E9-F9 -> 22.243088 | H9: =IF(AND(A9>Inputs!$B$21,A9<=Inputs!$B$21+Inputs!$B$12),Capitalization!C$12,0) -> 8.5084163 | I9: =G9-H9 -> 13.734671 | J9: =IF(A9<=Inputs!$B$21,"",IF(AND(A9<=Inputs!$B$22,Capitalization!C$18>0),Inputs!$B$25,Inputs!$B$26)) -> 0.7 | K9: =IF(A9=0,-Capitalization!C$19,IF(A9<=Inputs!$B$21,0,I9*J9-IF(AND(A9=Inputs!$B$22,Capitalization!C$18>0),Inputs!$B$23,0))) -> 9.6142699 | L9: =IF(H9>0,G9/H9,"") -> 2.6142453 | M9: =IF(A9=0,-Capitalization!C$4,IF(A9<=Inputs!$B$21,0,G9)) -> 22.243088
A10: 5 | B10: =IF(A10=0,"Equity",IF(A10<=Inputs!$B$21,"Construction",IF(A10<=Inputs!$B$21+Inputs!$B$5,"Queue wait",IF(A10<=Inputs!$B$21+Configurations!$B$15,"Grid ops"," ")))) -> Queue wait | C10: =IF(A10<=Inputs!$B$21,"",A10-Inputs!$B$21-1) -> 2 | D10: =IF(OR(A10<=Inputs!$B$21,A10>Inputs!$B$21+Configurations!$B$15),0,Configurations!$B$4*Configurations!$B$5*8760*(1-Configurations!$B$6)^C10*Configurations!$B$7*(1-Configurations!$B$8)) -> 227883.9 | E10: =IF(OR(A10<=Inputs!$B$21,A10>Inputs!$B$21+Configurations!$B$15),0,IF(A10<=Inputs!$B$21+Inputs!$B$5,D10*(1-Inputs!$B$10)*Configurations!$B$16/1000000,D10*Inputs!$B$18/1000000)) -> 27.356022 | F10: =IF(OR(A10<=Inputs!$B$21,A10>Inputs!$B$21+Configurations!$B$15),0,Configurations!$B$12+Configurations!$B$13+Configurations!$B$14+Inputs!$B$20*E10) -> 5.2483403 | G10: =E10-F10 -> 22.107682 | H10: =IF(AND(A10>Inputs!$B$21,A10<=Inputs!$B$21+Inputs!$B$12),Capitalization!C$12,0) -> 8.5084163 | I10: =G10-H10 -> 13.599266 | J10: =IF(A10<=Inputs!$B$21,"",IF(AND(A10<=Inputs!$B$22,Capitalization!C$18>0),Inputs!$B$25,Inputs!$B$26)) -> 0.7 | K10: =IF(A10=0,-Capitalization!C$19,IF(A10<=Inputs!$B$21,0,I10*J10-IF(AND(A10=Inputs!$B$22,Capitalization!C$18>0),Inputs!$B$23,0))) -> 9.5194861 | L10: =IF(H10>0,G10/H10,"") -> 2.598331 | M10: =IF(A10=0,-Capitalization!C$4,IF(A10<=Inputs!$B$21,0,G10)) -> 22.107682
