Workbook

Sheet Inputs
A1: SPUR Preliminary Co-location Model v7 — per-configuration tabs
A2: Three yellow levers apply to ALL configurations simultaneously (keeps cross-config comparison consistent). Blue = editable. $ in millions.
A4: SCENARIO LEVERS (GLOBAL)
A5: Queue wait (mech. completion -> COD), years | B5: 4 | C5: Test 2/4/6/8 (LBNL Queued Up 2025: https://emp.lbl.gov/queues)
A6: ITC rate | B6: 0.3 | C6: 0% = OBBBA Scenario D (zero credit under EITHER credit type); 30% = full rate w/ PWA
A7: Credit type (1=ITC, 2=PTC) | B7: 1 | C7: Framework 2.3.5: run both; PTC uses full depreciable basis
A8: SHARED PARAMETERS
A9: PTC rate ($/MWh, full rate w/ PWA) | B9: 15 | C9: $0.015/kWh, 10-yr duration (Framework 2.3.4; inflation adjustment omitted)
A10: BESS delivery loss (RTE approx.) | B10: 0.01 | C10: Annual approximation of round-trip losses
A11: Debt interest rate | B11: 0.055 | C11: Framework 2.3.1: 5-7% range
A12: Debt tenor (years) | B12: 20 | C12: Framework 2.3.1
A13: Target DSCR (debt sizing) | B13: 1.35 | C13: Framework 2.7
A14: Max leverage (% of total capital) | B14: 0.55 | C14: Framework 2.3.1: 50-55%; binds when DSCR-sized debt exceeds it (wind, geothermal)
A15: Combined tax rate (fed + CA) | B15: 0.2984 | C15: 21% federal + 8.84% CA
A16: Tax equity pay rate (per $ benefit PV) | B16: 0.8 | C16: TE pays ~80c per $1 PV of ITC + PTC + MACRS shield
A17: MACRS PV discount rate | B17: 0.07 | C17: Assumption
A18: Grid hybrid PPA price ($/MWh) | B18: 72 | C18: LBNL Utility-Scale Solar (hybrid PPA levels): https://emp.lbl.gov/utility-scale-solar
A19: BTM PPA price ($/MWh) | B19: 60 | C19: ~17% discount, within 10-20% industry range (Framework 4.3)
A20: Asset management (% of revenue) | B20: 0.015 | C20: Framework 2.6
... A26: Developer cash share, post-flip | B26: 0.975 | C26: Framework 2.8.2

Sheet Configurations
A1: Configuration library — each parameter feeds its configuration's tabs directly
A3: Parameter | B3: Solar+BESS 100MW | C3: Wind+BESS 150MW | D3: Geothermal+BESS 100MW | E3: Source / note
A4: Capacity (MW) | B4: 100 | C4: 150 | D4: 100 | E4: Solar/Geothermal: Framework 2.2.1. Wind: 150 MW scale variant (user-specified)
A5: Capacity factor | B5: 0.275 | C5: 0.35 | D5: 0.9 | E5: Solar: CA midpoint. Wind: upper Tehachapi 30-35%. Geothermal: 90%+ Salton Sea/Imperial Valley (NREL ATB 2024: https://atb.nrel.gov/electricity/2024/technologies)
A6: Annual degradation | B6: 0.005 | C6: 0.002 | D6: 0 | E6: Framework 2.5.2 (geothermal ~0%)
A7: Availability | B7: 0.98 | C7: 0.96 | D7: 0.95 | E7: Framework 2.5.2
A8: Electrical losses | B8: 0.025 | C8: 0.025 | D8: 0.025 | E8: Framework 2.5.2
A9: Total CAPEX ($mm) | B9: 197 | C9: 321.4 | D9: 568.25 | E9: Solar: Framework 2.2.3. Wind: $1,350/kW x150 + BESS 75MW/300MWh @$1,250/kW + dev 4% + land + intercon. Geothermal: $5,000/kW x100 + BESS 25MW/50MWh + dev 4% + land + intercon (NREL ATB 2024 midpoints)
A10: Qualified investment ($mm) | B10: 180 | C10: 296.25 | D10: 531.25 | E10: Generation + BESS only (Framework 2.2.4)
A11: Microgrid CAPEX ($mm) | B11: 12 | C11: 18 | D11: 12 | E11: $120/kW midpoint of $50-150/kW x capacity
A12: Fixed O&M, gen + BESS ($mm/yr) | B12: 3 | C12: 6.375 | D12: 4.625 | E12: Framework 2.6 midpoints per configuration
A13: Land lease + insurance ($mm/yr) | B13: 1.088 | C13: 1.586 | D13: 2.573 | E13: $0.3mm land + 0.4% of CAPEX insurance
A14: Microgrid O&M ($mm/yr) | B14: 0.75 | C14: 1.125 | D14: 0.75 | E14: $7.5/kW-yr x capacity
A15: Operating life (years) | B15: 25 | C15: 25 | D15: 30 | E15: Framework 2.1: 25 yrs solar/wind, 30 yrs geothermal
A18: Notes: (1) Model finds ITC > PTC for all three configurations at these parameters — for geothermal this contradicts Framework 2.3.5's
A19: expectation; sensitive to the omitted PTC inflation adjustment and the 7% discount on the PTC stream. (2) Geothermal faces no near-term
A20: OBBBA deadline (phaseout from 2034), so the 0% ITC scenario is a stress test rather than a live policy risk for that configuration.

Sheet Capitalization
A1: Capitalization — debt = MIN(DSCR-sized, max leverage x capital); tax equity sized to ITC/PTC + MACRS shield
B3: Solar Base | C3: Solar Coloc | D3: Wind Base | E3: Wind Coloc | F3: Geo Base | G3: Geo Coloc
A4: Total capital required ($mm) | B4: =Configurations!$B$9 -> 197 | C4: =Configurations!$B$9+Configurations!$B$11 -> 209 | D4: =Configurations!$C$9 -> 321.4 | E4: =Configurations!$C$9+Configurations!$C$11 -> 339.4 | F4: =Configurations!$D$9 -> 568.25 | G4: =Configurations!$D$9+Configurations!$D$11 -> 580.25
A5: First grid-year net energy (MWh) | B5: =Configurations!$B$4*Configurations!$B$5*8760*Configurations!$B$7*(1-Configurations!$B$8) -> 230179.95 | C5: =Configurations!$B$4*Configurations!$B$5*8760*Configurations!$B$7*(1-Configurations!$B$8) -> 230179.95 | D5: =Configurations!$C$4*Configurations!$C$5*8760*Configurations!$C$7*(1-Configurations!$C$8) -> 430466.4 | E5: =Configurations!$C$4*Configurations!$C$5*8760*Configurations!$C$7*(1-Configurations!$C$8) -> 430466.4 | F5: =Configurations!$D$4*Configurations!$D$5*8760*Configurations!$D$7*(1-Configurations!$D$8) -> 730255.5 | G5: =Configurations!$D$4*Configurations!$D$5*8760*Configurations!$D$7*(1-Configurations!$D$8) -> 730255.5
A6: First grid-year revenue ($mm) | B6: =B5*Inputs!$B$18/1000000 -> 16.572956 | C6: =C5*Inputs!$B$18/1000000 -> 16.572956 | D6: =D5*Inputs!$B$18/1000000 -> 30.993581 | E6: =E5*Inputs!$B$18/1000000 -> 30.993581 | F6: =F5*Inputs!$B$18/1000000 -> 52.578396 | G6: =G5*Inputs!$B$18/1000000 -> 52.578396
A7: First grid-year OPEX ($mm) | B7: =Configurations!$B$12+Configurations!$B$13+Inputs!$B$20*B6 -> 4.3365943 | C7: =Configurations!$B$12+Configurations!$B$13+Configurations!$B$14+Inputs!$B$20*C6 -> 5.0865943 | D7: =Configurations!$C$12+Configurations!$C$13+Inputs!$B$20*D6 -> 8.4259037 | E7: =Configurations!$C$12+Configurations!$C$13+Configurations!$C$14+Inputs!$B$20*E6 -> 9.5509037 | F7: =Configurations!$D$12+Configurations!$D$13+Inputs!$B$20*F6 -> 7.9866759 | G7: =Configurations!$D$12+Configurations!$D$13+Configurations!$D$14+Inputs!$B$20*G6 -> 8.7366759
A8: First grid-year EBITDA ($mm) | B8: =B6-B7 -> 12.236362 | C8: =C6-C7 -> 11.486362 | D8: =D6-D7 -> 22.567677 | E8: =E6-E7 -> 21.442677 | F8: =F6-F7 -> 44.59172 | G8: =G6-G7 -> 43.84172
A9: Max debt service @ DSCR ($mm/yr) | B9: =B8/Inputs!$B$13 -> 9.0639719 | C9: =C8/Inputs!$B$13 -> 8.5084163 | D9: =D8/Inputs!$B$13 -> 16.716798 | E9: =E8/Inputs!$B$13 -> 15.883465 | F9: =F8/Inputs!$B$13 -> 33.030904 | G9: =G8/Inputs!$B$13 -> 32.475348
A10: DSCR-sized debt ($mm) | B10: =B9*(1-(1+Inputs!$B$11)^-Inputs!$B$12)/Inputs!$B$11 -> 108.31793 | C10: =C9*(1-(1+Inputs!$B$11)^-Inputs!$B$12)/Inputs!$B$11 -> 101.67883 | D10: =D9*(1-(1+Inputs!$B$11)^-Inputs!$B$12)/Inputs!$B$11 -> 199.77213 | E10: =E9*(1-(1+Inputs!$B$11)^-Inputs!$B$12)/Inputs!$B$11 -> 189.81348 | F10: =F9*(1-(1+Inputs!$B$11)^-Inputs!$B$12)/Inputs!$B$11 -> 394.73193 | G10: =G9*(1-(1+Inputs!$B$11)^-Inputs!$B$12)/Inputs!$B$11 -> 388.09283
A11: Senior debt after leverage cap ($mm) | B11: =MIN(B10,Inputs!$B$14*B4) -> 108.31793 | C11: =MIN(C10,Inputs!$B$14*C4) -> 101.67883 | D11: =MIN(D10,Inputs!$B$14*D4) -> 176.77 | E11: =MIN(E10,Inputs!$B$14*E4) -> 186.67 | F11: =MIN(F10,Inputs!$B$14*F4) -> 312.5375 | G11: =MIN(G10,Inputs!$B$14*G4) -> 319.1375
A12: Actual debt service ($mm/yr) | B12: =B11/((1-(1+Inputs!$B$11)^-Inputs!$B$12)/Inputs!$B$11) -> 9.0639719 | C12: =C11/((1-(1+Inputs!$B$11)^-Inputs!$B$12)/Inputs!$B$11) -> 8.5084163 | D12: =D11/((1-(1+Inputs!$B$11)^-Inputs!$B$12)/Inputs!$B$11) -> 14.791995 | E12: =E11/((1-(1+Inputs!$B$11)^-Inputs!$B$12)/Inputs!$B$11) -> 15.620421 | F12: =F11/((1-(1+Inputs!$B$11)^-Inputs!$B$12)/Inputs!$B$11) -> 26.152929 | G12: =G11/((1-(1+Inputs!$B$11)^-Inputs!$B$12)/Inputs!$B$11) -> 26.705212
A13: ITC amount ($mm) | B13: =IF(Inputs!$B$7=1,Configurations!$B$10*Inputs!$B$6,0) -> 54 | C13: =IF(Inputs!$B$7=1,Configurations!$B$10*Inputs!$B$6,0) -> 54 | D13: =IF(Inputs!$B$7=1,Configurations!$C$10*Inputs!$B$6,0) -> 88.875 | E13: =IF(Inputs!$B$7=1,Configurations!$C$10*Inputs!$B$6,0) -> 88.875 | F13: =IF(Inputs!$B$7=1,Configurations!$D$10*Inputs!$B$6,0) -> 159.375 | G13: =IF(Inputs!$B$7=1,Configurations!$D$10*Inputs!$B$6,0) -> 159.375
A14: PTC start year (calendar) | B14: =Inputs!$B$21+Inputs!$B$5+1 -> 7 | C14: =Inputs!$B$21+1 -> 3 | D14: =Inputs!$B$21+Inputs!$B$5+1 -> 7 | E14: =Inputs!$B$21+1 -> 3 | F14: =Inputs!$B$21+Inputs!$B$5+1 -> 7 | G14: =Inputs!$B$21+1 -> 3
A15: PTC stream PV ($mm) | B15: =IF(Inputs!$B$7=2,B5*Inputs!$B$9/1000000*(1-(1+Inputs!$B$17)^-10)/Inputs!$B$17/(1+Inputs!$B$17)^(B14-1),0) -> 0 | C15: =IF(Inputs!$B$7=2,C5*Inputs!$B$9/1000000*(1-(1+Inputs!$B$17)^-10)/Inputs!$B$17/(1+Inputs!$B$17)^(C14-1),0) -> 0 | D15: =IF(Inputs!$B$7=2,D5*Inputs!$B$9/1000000*(1-(1+Inputs!$B$17)^-10)/Inputs!$B$17/(1+Inputs!$B$17)^(D14-1),0) -> 0 | E15: =IF(Inputs!$B$7=2,E5*Inputs!$B$9/1000000*(1-(1+Inputs!$B$17)^-10)/Inputs!$B$17/(1+Inputs!$B$17)^(E14-1),0) -> 0 | F15: =IF(Inputs!$B$7=2,F5*Inputs!$B$9/1000000*(1-(1+Inputs!$B$17)^-10)/Inputs!$B$17/(1+Inputs!$B$17)^(F14-1),0) -> 0 | G15: =IF(Inputs!$B$7=2,G5*Inputs!$B$9/1000000*(1-(1+Inputs!$B$17)^-10)/Inputs!$B$17/(1+Inputs!$B$17)^(G14-1),0) -> 0
A16: Depreciable basis ($mm) | B16: =IF(Inputs!$B$7=1,Configurations!$B$10-0.5*B13,Configurations!$B$10) -> 153 | C16: =IF(Inputs!$B$7=1,Configurations!$B$10-0.5*C13,Configurations!$B$10) -> 153 | D16: =IF(Inputs!$B$7=1,Configurations!$C$10-0.5*D13,Configurations!$C$10) -> 251.8125 | E16: =IF(Inputs!$B$7=1,Configurations!$C$10-0.5*E13,Configurations!$C$10) -> 251.8125 | F16: =IF(Inputs!$B$7=1,Configurations!$D$10-0.5*F13,Configurations!$D$10) -> 451.5625 | G16: =IF(Inputs!$B$7=1,Configurations!$D$10-0.5*G13,Configurations!$D$10) -> 451.5625
A17: MACRS shield PV ($mm) | B17: =SUMPRODUCT($B$25:$B$30,B16*Inputs!$B$15/(1+Inputs!$B$17)^ROW(INDIRECT("1:6"))) -> 37.964505 | C17: =SUMPRODUCT($B$25:$B$30,C16*Inputs!$B$15/(1+Inputs!$B$17)^ROW(INDIRECT("1:6"))) -> 37.964505 | D17: =SUMPRODUCT($B$25:$B$30,D16*Inputs!$B$15/(1+Inputs!$B$17)^ROW(INDIRECT("1:6"))) -> 62.483248 | E17: =SUMPRODUCT($B$25:$B$30,E16*Inputs!$B$15/(1+Inputs!$B$17)^ROW(INDIRECT("1:6"))) -> 62.483248 | F17: =SUMPRODUCT($B$25:$B$30,F16*Inputs!$B$15/(1+Inputs!$B$17)^ROW(INDIRECT("1:6"))) -> 112.04802 | G17: =SUMPRODUCT($B$25:$B$30,G16*Inputs!$B$15/(1+Inputs!$B$17)^ROW(INDIRECT("1:6"))) -> 112.04802
A18: Tax equity contribution ($mm) | B18: =IF(Inputs!$B$6=0,0,Inputs!$B$16*(B13+B15+B17)) -> 73.571604 | C18: =IF(Inputs!$B$6=0,0,Inputs!$B$16*(C13+C15+C17)) -> 73.571604 | D18: =IF(Inputs!$B$6=0,0,Inputs!$B$16*(D13+D15+D17)) -> 121.0866 | E18: =IF(Inputs!$B$6=0,0,Inputs!$B$16*(E13+E15+E17)) -> 121.0866 | F18: =IF(Inputs!$B$6=0,0,Inputs!$B$16*(F13+F15+F17)) -> 217.13841 | G18: =IF(Inputs!$B$6=0,0,Inputs!$B$16*(G13+G15+G17)) -> 217.13841
A19: Developer equity ($mm) | B19: =B4-B11-B18 -> 15.110465 | C19: =C4-C11-C18 -> 33.749566 | D19: =D4-D11-D18 -> 23.543402 | E19: =E4-E11-E18 -> 31.643402 | F19: =F4-F11-F18 -> 38.574086 | G19: =G4-G11-G18 -> 43.974086
A21: PTC start assumption: baseline is not placed in service while idle (PTC begins at COD); co-location BTM operation is assumed
A22: to qualify as placed in service (PTC begins at mechanical completion). Open tax question — validate in practitioner interviews.
A24: MACRS 5-yr schedule (Framework 2.3.3)
A25: Year 1 | B25: 0.2
A26: Year 2 | B26: 0.32
A27: Year 3 | B27: 0.192
A28: Year 4 | B28: 0.1152
A29: Year 5 | B29: 0.1152
A30: Year 6 | B30: 0.0576

Sheet SolarBase
A1: SolarBase — annual cash flow waterfall ($mm)
A2: Developer levered IRR: | B2: =IRR(K5:K37) -> 0.040713705 | C2: Unlevered (project) IRR: | D2: =IRR(M5:M37) -> 0.0091238666 | E2: NPV of dev cash @ discount rate ($mm): | F2: =K5+NPV(Inputs!$B$24,K6:K37) -> -15.39658
A4: Year | B4: Phase | C4: Op yr | D4: Net energy (MWh) | E4: Revenue | F4: OPEX | G4: EBITDA | H4: Debt service | I4: Distributable cash | J4: Dev share | K4: Dev cash flow | L4: DSCR | M4: Project CF (unlevered)
A5: 0 | B5: =IF(A5=0,"Equity",IF(A5<=Inputs!$B$21,"Construction",IF(A5<=Inputs!$B$21+Inputs!$B$5,"Queue wait",IF(A5<=Inputs!$B$21+Configurations!$B$15,"Grid ops","—")))) -> Equity | C5: =IF(A5<=Inputs!$B$21,"",A5-Inputs!$B$21-1) | D5: =IF(OR(A5<=Inputs!$B$21,A5>Inputs!$B$21+Configurations!$B$15),0,Configurations!$B$4*Configurations!$B$5*8760*(1-Configurations!$B$6)^C5*Configurations!$B$7*(1-Configurations!$B$8)) -> 0 | E5: =IF(OR(A5<=Inputs!$B$21,A5>Inputs!$B$21+Configurations!$B$15),0,IF(A5<=Inputs!$B$21+Inputs!$B$5,0,D5*Inputs!$B$18/1000000)) -> 0 | F5: =IF(OR(A5<=Inputs!$B$21,A5>Inputs!$B$21+Configurations!$B$15),0,IF(A5<=Inputs!$B$21+Inputs!$B$5,Configurations!$B$13,Configurations!$B$12+Configurations!$B$13+Inputs!$B$20*E5)) -> 0 | G5: =E5-F5 -> 0 | H5: =IF(AND(A5>Inputs!$B$21,A5<=Inputs!$B$21+Inputs!$B$12),Capitalization!B$12,0) -> 0 | I5: =G5-H5 -> 0 | J5: =IF(A5<=Inputs!$B$21,"",IF(AND(A5<=Inputs!$B$22,Capitalization!B$18>0),Inputs!$B$25,Inputs!$B$26)) | K5: =IF(A5=0,-Capitalization!B$19,IF(A5<=Inputs!$B$21,0,I5*J5-IF(AND(A5=Inputs!$B$22,Capitalization!B$18>0),Inputs!$B$23,0))) -> -15.110465 | L5: =IF(H5>0,G5/H5,"") | M5: =IF(A5=0,-Capitalization!B$4,IF(A5<=Inputs!$B$21,0,G5)) -> -197
A6: 1 | B6: =IF(A6=0,"Equity",IF(A6<=Inputs!$B$21,"Construction",IF(A6<=Inputs!$B$21+Inputs!$B$5,"Queue wait",IF(A6<=Inputs!$B$21+Configurations!$B$15,"Grid ops","—")))) -> Construction | C6: =IF(A6<=Inputs!$B$21,"",A6-Inputs!$B$21-1) | D6: =IF(OR(A6<=Inputs!$B$21,A6>Inputs!$B$21+Configurations!$B$15),0,Configurations!$B$4*Configurations!$B$5*8760*(1-Configurations!$B$6)^C6*Configurations!$B$7*(1-Configurations!$B$8)) -> 0 | E6: =IF(OR(A6<=Inputs!$B$21,A6>Inputs!$B$21+Configurations!$B$15),0,IF(A6<=Inputs!$B$21+Inputs!$B$5,0,D6*Inputs!$B$18/1000000)) -> 0 | F6: =IF(OR(A6<=Inputs!$B$21,A6>Inputs!$B$21+Configurations!$B$15),0,IF(A6<=Inputs!$B$21+Inputs!$B$5,Configurations!$B$13,Configurations!$B$12+Configurations!$B$13+Inputs!$B$20*E6)) -> 0 | G6: =E6-F6 -> 0 | H6: =IF(AND(A6>Inputs!$B$21,A6<=Inputs!$B$21+Inputs!$B$12),Capitalization!B$12,0) -> 0 | I6: =G6-H6 -> 0 | J6: =IF(A6<=Inputs!$B$21,"",IF(AND(A6<=Inputs!$B$22,Capitalization!B$18>0),Inputs!$B$25,Inputs!$B$26)) | K6: =IF(A6=0,-Capitalization!B$19,IF(A6<=Inputs!$B$21,0,I6*J6-IF(AND(A6=Inputs!$B$22,Capitalization!B$18>0),Inputs!$B$23,0))) -> 0 | L6: =IF(H6>0,G6/H6,"") | M6: =IF(A6=0,-Capitalization!B$4,IF(A6<=Inputs!$B$21,0,G6)) -> 0
A7: 2 | B7: =IF(A7=0,"Equity",IF(A7<=Inputs!$B$21,"Construction",IF(A7<=Inputs!$B$21+Inputs!$B$5,"Queue wait",IF(A7<=Inputs!$B$21+Configurations!$B$15,"Grid ops","—")))) -> Construction | C7: =IF(A7<=Inputs!$B$21,"",A7-Inputs!$B$21-1) | D7: =IF(OR(A7<=Inputs!$B$21,A7>Inputs!$B$21+Configurations!$B$15),0,Configurations!$B$4*Configurations!$B$5*8760*(1-Configurations!$B$6)^C7*Configurations!$B$7*(1-Configurations!$B$8)) -> 0 | E7: =IF(OR(A7<=Inputs!$B$21,A7>Inputs!$B$21+Configurations!$B$15),0,IF(A7<=Inputs!$B$21+Inputs!$B$5,0,D7*Inputs!$B$18/1000000)) -> 0 | F7: =IF(OR(A7<=Inputs!$B$21,A7>Inputs!$B$21+Configurations!$B$15),0,IF(A7<=Inputs!$B$21+Inputs!$B$5,Configurations!$B$13,Configurations!$B$12+Configurations!$B$13+Inputs!$B$20*E7)) -> 0 | G7: =E7-F7 -> 0 | H7: =IF(AND(A7>Inputs!$B$21,A7<=Inputs!$B$21+Inputs!$B$12),Capitalization!B$12,0) -> 0 | I7: =G7-H7 -> 0 | J7: =IF(A7<=Inputs!$B$21,"",IF(AND(A7<=Inputs!$B$22,Capitalization!B$18>0),Inputs!$B$25,Inputs!$B$26)) | K7: =IF(A7=0,-Capitalization!B$19,IF(A7<=Inputs!$B$21,0,I7*J7-IF(AND(A7=Inputs!$B$22,Capitalization!B$18>0),Inputs!$B$23,0))) -> 0 | L7: =IF(H7>0,G7/H7,"") | M7: =IF(A7=0,-Capitalization!B$4,IF(A7<=Inputs!$B$21,0,G7)) -> 0
A8: 3 | B8: =IF(A8=0,"Equity",IF(A8<=Inputs!$B$21,"Construction",IF(A8<=Inputs!$B$21+Inputs!$B$5,"Queue wait",IF(A8<=Inputs!$B$21+Configurations!$B$15,"Grid ops","—")))) -> Queue wait | C8: =IF(A8<=Inputs!$B$21,"",A8-Inputs!$B$21-1) -> 0 | D8: =IF(OR(A8<=Inputs!$B$21,A8>Inputs!$B$21+Configurations!$B$15),0,Configurations!$B$4*Configurations!$B$5*8760*(1-Configurations!$B$6)^C8*Configurations!$B$7*(1-Configurations!$B$8)) -> 230179.95 | E8: =IF(OR(A8<=Inputs!$B$21,A8>Inputs!$B$21+Configurations!$B$15),0,IF(A8<=Inputs!$B$21+Inputs!$B$5,0,D8*Inputs!$B$18/1000000)) -> 0 | F8: =IF(OR(A8<=Inputs!$B$21,A8>Inputs!$B$21+Configurations!$B$15),0,IF(A8<=Inputs!$B$21+Inputs!$B$5,Configurations!$B$13,Configurations!$B$12+Configurations!$B$13+Inputs!$B$20*E8)) -> 1.088 | G8: =E8-F8 -> -1.088 | H8: =IF(AND(A8>Inputs!$B$21,A8<=Inputs!$B$21+Inputs!$B$12),Capitalization!B$12,0) -> 9.0639719 | I8: =G8-H8 -> -10.151972 | J8: =IF(A8<=Inputs!$B$21,"",IF(AND(A8<=Inputs!$B$22,Capitalization!B$18>0),Inputs!$B$25,Inputs!$B$26)) -> 0.7 | K8: =IF(A8=0,-Capitalization!B$19,IF(A8<=Inputs!$B$21,0,I8*J8-IF(AND(A8=Inputs!$B$22,Capitalization!B$18>0),Inputs!$B$23,0))) -> -7.1063803 | L8: =IF(H8>0,G8/H8,"") -> -0.12003568 | M8: =IF(A8=0,-Capitalization!B$4,IF(A8<=Inputs!$B$21,0,G8)) -> -1.088
A9: 4 | B9: =IF(A9=0,"Equity",IF(A9<=Inputs!$B$21,"Construction",IF(A9<=Inputs!$B$21+Inputs!$B$5,"Queue wait",IF(A9<=Inputs!$B$21+Configurations!$B$15,"Grid ops","—")))) -> Queue wait | C9: =IF(A9<=Inputs!$B$21,"",A9-Inputs!$B$21-1) -> 1 | D9: =IF(OR(A9<=Inputs!$B$21,A9>Inputs!$B$21+Configurations!$B$15),0,Configurations!$B$4*Configurations!$B$5*8760*(1-Configurations!$B$6)^C9*Configurations!$B$7*(1-Configurations!$B$8)) -> 229029.05 | E9: =IF(OR(A9<=Inputs!$B$21,A9>Inputs!$B$21+Configurations!$B$15),0,IF(A9<=Inputs!$B$21+Inputs!$B$5,0,D9*Inputs!$B$18/1000000)) -> 0 | F9: =IF(OR(A9<=Inputs!$B$21,A9>Inputs!$B$21+Configurations!$B$15),0,IF(A9<=Inputs!$B$21+Inputs!$B$5,Configurations!$B$13,Configurations!$B$12+Configurations!$B$13+Inputs!$B$20*E9)) -> 1.088 | G9: =E9-F9 -> -1.088 | H9: =IF(AND(A9>Inputs!$B$21,A9<=Inputs!$B$21+Inputs!$B$12),Capitalization!B$12,0) -> 9.0639719 | I9: =G9-H9 -> -10.151972 | J9: =IF(A9<=Inputs!$B$21,"",IF(AND(A9<=Inputs!$B$22,Capitalization!B$18>0),Inputs!$B$25,Inputs!$B$26)) -> 0.7 | K9: =IF(A9=0,-Capitalization!B$19,IF(A9<=Inputs!$B$21,0,I9*J9-IF(AND(A9=Inputs!$B$22,Capitalization!B$18>0),Inputs!$B$23,0))) -> -7.1063803 | L9: =IF(H9>0,G9/H9,"") -> -0.12003568 | M9: =IF(A9=0,-Capitalization!B$4,IF(A9<=Inputs!$B$21,0,G9)) -> -1.088
A10: 5 | B10: =IF(A10=0,"Equity",IF(A10<=Inputs!$B$21,"Construction",IF(A10<=Inputs!$B$21+Inputs!$B$5,"Queue wait",IF(A10<=Inputs!$B$21+Configurations!$B$15,"Grid ops","—")))) -> Queue wait | C10: =IF(A10<=Inputs!$B$21,"",A10-Inputs!$B$21-1) -> 2 | D10: =IF(OR(A10<=Inputs!$B$21,A10>Inputs!$B$21+Configurations!$B$15),0,Configurations!$B$4*Configurations!$B$5*8760*(1-Configurations!$B$6)^C10*Configurations!$B$7*(1-Configurations!$B$8)) -> 227883.9 | E10: =IF(OR(A10<=Inputs!$B$21,A10>Inputs!$B$21+Configurations!$B$15),0,IF(A10<=Inputs!$B$21+Inputs!$B$5,0,D10*Inputs!$B$18/1000000)) -> 0 | F10: =IF(OR(A10<=Inputs!$B$21,A10>Inputs!$B$21+Configurations!$B$15),0,IF(A10<=Inputs!$B$21+Inputs!$B$5,Configurations!$B$13,Configurations!$B$12+Configurations!$B$13+Inputs!$B$20*E10)) -> 1.088 | G10: =E10-F10 -> -1.088 | H10: =IF(AND(A10>Inputs!$B$21,A10<=Inputs!$B$21+Inputs!$B$12),Capitalization!B$12,0) -> 9.0639719 | I10: =G10-H10 -> -10.151972 | J10: =IF(A10<=Inputs!$B$21,"",IF(AND(A10<=Inputs!$B$22,Capitalization!B$18>0),Inputs!$B$25,Inputs!$B$26)) -> 0.7 | K10: =IF(A10=0,-Capitalization!B$19,IF(A10<=Inputs!$B$21,0,I10*J10-IF(AND(A10=Inputs!$B$22,Capitalization!B$18>0),Inputs!$B$23,0))) -> -7.1063803 | L10: =IF(H10>0,G10/H10,"") -> -0.12003568 | M10: =IF(A10=0,-Capitalization!B$4,IF(A10<=Inputs!$B$21,0,G10)) -> -1.088
A11: 6 | B11: =IF(A11=0,"Equity",IF(A11<=Inputs!$B$21,"Construction",IF(A11<=Inputs!$B$21+Inputs!$B$5,"Queue wait",IF(A11<=Inputs!$B$21+Configurations!$B$15,"Grid ops","—")))) -> Queue wait | C11: =IF(A11<=Inputs!$B$21,"",A11-Inputs!$B$21-1) -> 3 | D11: =IF(OR(A11<=Inputs!$B$21,A11>Inputs!$B$21+Configurations!$B$15),0,Configurations!$B$4*Configurations!$B$5*8760*(1-Configurations!$B$6)^C11*Configurations!$B$7*(1-Configurations!$B$8)) -> 226744.49 | E11: =IF(OR(A11<=Inputs!$B$21,A11>Inputs!$B$21+Configurations!$B$15),0,IF(A11<=Inputs!$B$21+Inputs!$B$5,0,D11*Inputs!$B$18/1000000)) -> 0 | F11: =IF(OR(A11<=Inputs!$B$21,A11>Inputs!$B$21+Configurations!$B$15),0,IF(A11<=Inputs!$B$21+Inputs!$B$5,Configurations!$B$13,Configurations!$B$12+Configurations!$B$13+Inputs!$B$20*E11)) -> 1.088 | G11: =E11-F11 -> -1.088 | H11: =IF(AND(A11>Inputs!$B$21,A11<=Inputs!$B$21+Inputs!$B$12),Capitalization!B$12,0) -> 9.0639719 | I11: =G11-H11 -> -10.151972 | J11: =IF(A11<=Inputs!$B$21,"",IF(AND(A11<=Inputs!$B$22,Capitalization!B$18>0),Inputs!$B$25,Inputs!$B$26)) -> 0.7 | K11: =IF(A11=0,-Capitalization!B$19,IF(A11<=Inputs!$B$21,0,I11*J11-IF(AND(A11=Inputs!$B$22,Capitalization!B$18>0),Inputs!$B$23,0))) -> -8.1063803 | L11: =IF(H11>0,G11/H11,"") -> -0.12003568 | M11: =IF(A11=0,-Capitalization!B$4,IF(A11<=Inputs!$B$21,0,G11)) -> -1.088
A12: 7 | B12: =IF(A12=0,"Equity",IF(A12<=Inputs!$B$21,"Construction",IF(A12<=Inputs!$B$21+Inputs!$B$5,"Queue wait",IF(A12<=Inputs!$B$21+Configurations!$B$15,"Grid ops","—")))) -> Grid ops | C12: =IF(A12<=Inputs!$B$21,"",A12-Inputs!$B$21-1) -> 4 | D12: =IF(OR(A12<=Inputs!$B$21,A12>Inputs!$B$21+Configurations!$B$15),0,Configurations!$B$4*Configurations!$B$5*8760*(1-Configurations!$B$6)^C12*Configurations!$B$7*(1-Configurations!$B$8)) -> 225610.76 | E12: =IF(OR(A12<=Inputs!$B$21,A12>Inputs!$B$21+Configurations!$B$15),0,IF(A12<=Inputs!$B$21+Inputs!$B$5,0,D12*Inputs!$B$18/1000000)) -> 16.243975 | F12: =IF(OR(A12<=Inputs!$B$21,A12>Inputs!$B$21+Configurations!$B$15),0,IF(A12<=Inputs!$B$21+Inputs!$B$5,Configurations!$B$13,Configurations!$B$12+Configurations!$B$13+Inputs!$B$20*E12)) -> 4.3316596 | G12: =E12-F12 -> 11.912315 | H12: =IF(AND(A12>Inputs!$B$21,A12<=Inputs!$B$21+Inputs!$B$12),Capitalization!B$12,0) -> 9.0639719 | I12: =G12-H12 -> 2.8483434 | J12: =IF(A12<=Inputs!$B$21,"",IF(AND(A12<=Inputs!$B$22,Capitalization!B$18>0),Inputs!$B$25,Inputs!$B$26)) -> 0.975 | K12: =IF(A12=0,-Capitalization!B$19,IF(A12<=Inputs!$B$21,0,I12*J12-IF(AND(A12=Inputs!$B$22,Capitalization!B$18>0),Inputs!$B$23,0))) -> 2.7771348 | L12: =IF(H12>0,G12/H12,"") -> 1.3142489 | M12: =IF(A12=0,-Capitalization!B$4,IF(A12<=Inputs!$B$21,0,G12)) -> 11.912315
A13: 8 | B13: =IF(A13=0,"Equity",IF(A13<=Inputs!$B$21,"Construction",IF(A13<=Inputs!$B$21+Inputs!$B$5,"Queue wait",IF(A13<=Inputs!$B$21+Configurations!$B$15,"Grid ops","—")))) -> Grid ops | C13: =IF(A13<=Inputs!$B$21,"",A13-Inputs!$B$21-1) -> 5 | D13: =IF(OR(A13<=Inputs!$B$21,A13>Inputs!$B$21+Configurations!$B$15),0,Configurations!$B$4*Configurations!$B$5*8760*(1-Configurations!$B$6)^C13*Configurations!$B$7*(1-Configurations!$B$8)) -> 224482.71 | E13: =IF(OR(A13<=Inputs!$B$21,A13>Inputs!$B$21+Configurations!$B$15),0,IF(A13<=Inputs!$B$21+Inputs!$B$5,0,D13*Inputs!$B$18/1000000)) -> 16.162755 | F13: =IF(OR(A13<=Inputs!$B$21,A13>Inputs!$B$21+Configurations!$B$15),0,IF(A13<=Inputs!$B$21+Inputs!$B$5,Configurations!$B$13,Configurations!$B$12+Configurations!$B$13+Inputs!$B$20*E13)) -> 4.3304413 | G13: =E13-F13 -> 11.832314 | H13: =IF(AND(A13>Inputs!$B$21,A13<=Inputs!$B$21+Inputs!$B$12),Capitalization!B$12,0) -> 9.0639719 | I13: =G13-H13 -> 2.7683418 | J13: =IF(A13<=Inputs!$B$21,"",IF(AND(A13<=Inputs!$B$22,Capitalization!B$18>0),Inputs!$B$25,Inputs!$B$26)) -> 0.975 | K13: =IF(A13=0,-Capitalization!B$19,IF(A13<=Inputs!$B$21,0,I13*J13-IF(AND(A13=Inputs!$B$22,Capitalization!B$18>0),Inputs!$B$23,0))) -> 2.6991333 | L13: =IF(H13>0,G13/H13,"") -> 1.3054226 | M13: =IF(A13=0,-Capitalization!B$4,IF(A13<=Inputs!$B$21,0,G13)) -> 11.832314
A14: 9 | B14: =IF(A14=0,"Equity",IF(A14<=Inputs!$B$21,"Construction",IF(A14<=Inputs!$B$21+Inputs!$B$5,"Queue wait",IF(A14<=Inputs!$B$21+Configurations!$B$15,"Grid ops","—")))) -> Grid ops | C14: =IF(A14<=Inputs!$B$21,"",A14-Inputs!$B$21-1) -> 6 | D14: =IF(OR(A14<=Inputs!$B$21,A14>Inputs!$B$21+Configurations!$B$15),0,Configurations!$B$4*Configurations!$B$5*8760*(1-Configurations!$B$6)^C14*Configurations!$B$7*(1-Configurations!$B$8)) -> 223360.3 | E14: =IF(OR(A14<=Inputs!$B$21,A14>Inputs!$B$21+Configurations!$B$15),0,IF(A14<=Inputs!$B$21+Inputs!$B$5,0,D14*Inputs!$B$18/1000000)) -> 16.081941 | F14: =IF(OR(A14<=Inputs!$B$21,A14>Inputs!$B$21+Configurations!$B$15),0,IF(A14<=Inputs!$B$21+Inputs!$B$5,Configurations!$B$13,Configurations!$B$12+Configurations!$B$13+Inputs!$B$20*E14)) -> 4.3292291 | G14: =E14-F14 -> 11.752712 | H14: =IF(AND(A14>Inputs!$B$21,A14<=Inputs!$B$21+Inputs!$B$12),Capitalization!B$12,0) -> 9.0639719 | I14: =G14-H14 -> 2.6887403 | J14: =IF(A14<=Inputs!$B$21,"",IF(AND(A14<=Inputs!$B$22,Capitalization!B$18>0),Inputs!$B$25,Inputs!$B$26)) -> 0.975 | K14: =IF(A14=0,-Capitalization!B$19,IF(A14<=Inputs!$B$21,0,I14*J14-IF(AND(A14=Inputs!$B$22,Capitalization!B$18>0),Inputs!$B$23,0))) -> 2.6215218 | L14: =IF(H14>0,G14/H14,"") -> 1.2966404 | M14: =IF(A14=0,-Capitalization!B$4,IF(A14<=Inputs!$B$21,0,G14)) -> 11.752712
A15: 10 | B15: =IF(A15=0,"Equity",IF(A15<=Inputs!$B$21,"Construction",IF(A15<=Inputs!$B$21+Inputs!$B$5,"Queue wait",IF(A15<=Inputs!$B$21+Configurations!$B$15,"Grid ops","—")))) -> Grid ops | C15: =IF(A15<=Inputs!$B$21,"",A15-Inputs!$B$21-1) -> 7 | D15: =IF(OR(A15<=Inputs!$B$21,A15>Inputs!$B$21+Configurations!$B$15),0,Configurations!$B$4*Configurations!$B$5*8760*(1-Configurations!$B$6)^C15*Configurations!$B$7*(1-Configurations!$B$8)) -> 222243.49 | E15: =IF(OR(A15<=Inputs!$B$21,A15>Inputs!$B$21+Configurations!$B$15),0,IF(A15<=Inputs!$B$21+Inputs!$B$5,0,D15*Inputs!$B$18/1000000)) -> 16.001532 | F15: =IF(OR(A15<=Inputs!$B$21,A15>Inputs!$B$21+Configurations!$B$15),0,IF(A15<=Inputs!$B$21+Inputs!$B$5,Configurations!$B$13,Configurations!$B$12+Configurations!$B$13+Inputs!$B$20*E15)) -> 4.328023 | G15: =E15-F15 -> 11.673509 | H15: =IF(AND(A15>Inputs!$B$21,A15<=Inputs!$B$21+Inputs!$B$12),Capitalization!B$12,0) -> 9.0639719 | I15: =G15-H15 -> 2.6095367 | J15: =IF(A15<=Inputs!$B$21,"",IF(AND(A15<=Inputs!$B$22,Capitalization!B$18>0),Inputs!$B$25,Inputs!$B$26)) -> 0.975 | K15: =IF(A15=0,-Capitalization!B$19,IF(A15<=Inputs!$B$21,0,I15*J15-IF(AND(A15=Inputs!$B$22,Capitalization!B$18>0),Inputs!$B$23,0))) -> 2.5442983 | L15: =IF(H15>0,G15/H15,"") -> 1.2879021 | M15: =IF(A15=0,-Capitalization!B$4,IF(A15<=Inputs!$B$21,0,G15)) -> 11.673509
A16: 11 | B16: =IF(A16=0,"Equity",IF(A16<=Inputs!$B$21,"Construction",IF(A16<=Inputs!$B$21+Inputs!$B$5,"Queue wait",IF(A16<=Inputs!$B$21+Configurations!$B$15,"Grid ops","—")))) -> Grid ops | C16: =IF(A16<=Inputs!$B$21,"",A16-Inputs!$B$21-1) -> 8 | D16: =IF(OR(A16<=Inputs!$B$21,A16>Inputs!$B$21+Configurations!$B$15),0,Configurations!$B$4*Configurations!$B$5*8760*(1-Configurations!$B$6)^C16*Configurations!$B$7*(1-Configurations!$B$8)) -> 221132.28 | E16: =IF(OR(A16<=Inputs!$B$21,A16>Inputs!$B$21+Configurations!$B$15),0,IF(A16<=Inputs!$B$21+Inputs!$B$5,0,D16*Inputs!$B$18/1000000)) -> 15.921524 | F16: =IF(OR(A16<=Inputs!$B$21,A16>Inputs!$B$21+Configurations!$B$15),0,IF(A16<=Inputs!$B$21+Inputs!$B$5,Configurations!$B$13,Configurations!$B$12+Configurations!$B$13+Inputs!$B$20*E16)) -> 4.3268229 | G16: =E16-F16 -> 11.594701 | H16: =IF(AND(A16>Inputs!$B$21,A16<=Inputs!$B$21+Inputs!$B$12),Capitalization!B$12,0) -> 9.0639719 | I16: =G16-H16 -> 2.5307292 | J16: =IF(A16<=Inputs!$B$21,"",IF(AND(A16<=Inputs!$B$22,Capitalization!B$18>0),Inputs!$B$25,Inputs!$B$26)) -> 0.975 | K16: =IF(A16=0,-Capitalization!B$19,IF(A16<=Inputs!$B$21,0,I16*J16-IF(AND(A16=Inputs!$B$22,Capitalization!B$18>0),Inputs!$B$23,0))) -> 2.4674609 | L16: =IF(H16>0,G16/H16,"") -> 1.2792075 | M16: =IF(A16=0,-Capitalization!B$4,IF(A16<=Inputs!$B$21,0,G16)) -> 11.594701
... A37: 32 | B37: =IF(A37=0,"Equity",IF(A37<=Inputs!$B$21,"Construction",IF(A37<=Inputs!$B$21+Inputs!$B$5,"Queue wait",IF(A37<=Inputs!$B$21+Configurations!$B$15,"Grid ops","—")))) -> — | C37: =IF(A37<=Inputs!$B$21,"",A37-Inputs!$B$21-1) -> 29 | D37: =IF(OR(A37<=Inputs!$B$21,A37>Inputs!$B$21+Configurations!$B$15),0,Configurations!$B$4*Configurations!$B$5*8760*(1-Configurations!$B$6)^C37*Configurations!$B$7*(1-Configurations!$B$8)) -> 0 | E37: =IF(OR(A37<=Inputs!$B$21,A37>Inputs!$B$21+Configurations!$B$15),0,IF(A37<=Inputs!$B$21+Inputs!$B$5,0,D37*Inputs!$B$18/1000000)) -> 0 | F37: =IF(OR(A37<=Inputs!$B$21,A37>Inputs!$B$21+Configurations!$B$15),0,IF(A37<=Inputs!$B$21+Inputs!$B$5,Configurations!$B$13,Configurations!$B$12+Configurations!$B$13+Inputs!$B$20*E37)) -> 0 | G37: =E37-F37 -> 0 | H37: =IF(AND(A37>Inputs!$B$21,A37<=Inputs!$B$21+Inputs!$B$12),Capitalization!B$12,0) -> 0 | I37: =G37-H37 -> 0 | J37: =IF(A37<=Inputs!$B$21,"",IF(AND(A37<=Inputs!$B$22,Capitalization!B$18>0),Inputs!$B$25,Inputs!$B$26)) -> 0.975 | K37: =IF(A37=0,-Capitalization!B$19,IF(A37<=Inputs!$B$21,0,I37*J37-IF(AND(A37=Inputs!$B$22,Capitalization!B$18>0),Inputs!$B$23,0))) -> 0 | L37: =IF(H37>0,G37/H37,"") | M37: =IF(A37=0,-Capitalization!B$4,IF(A37<=Inputs!$B$21,0,G37)) -> 0

Sheet SolarColoc
A1: SolarColoc — annual cash flow waterfall ($mm)
A2: Developer levered IRR: | B2: =IRR(K5:K37) -> 0.044070577 | C2: Unlevered (project) IRR: | D2: =IRR(M5:M37) -> 0.012821957 | E2: NPV of dev cash @ discount rate ($mm): | F2: =K5+NPV(Inputs!$B$24,K6:K37) -> -15.39725
A4: Year | B4: Phase | C4: Op yr | D4: Net energy (MWh) | E4: Revenue | F4: OPEX | G4: EBITDA | H4: Debt service | I4: Distributable cash | J4: Dev share | K4: Dev cash flow | L4: DSCR | M4: Project CF (unlevered)
A5: 0 | B5: =IF(A5=0,"Equity",IF(A5<=Inputs!$B$21,"Construction",IF(A5<=Inputs!$B$21+Inputs!$B$5,"Queue wait",IF(A5<=Inputs!$B$21+Configurations!$B$15,"Grid ops","—")))) -> Equity | C5: =IF(A5<=Inputs!$B$21,"",A5-Inputs!$B$21-1) | D5: =IF(OR(A5<=Inputs!$B$21,A5>Inputs!$B$21+Configurations!$B$15),0,Configurations!$B$4*Configurations!$B$5*8760*(1-Configurations!$B$6)^C5*Configurations!$B$7*(1-Configurations!$B$8)) -> 0 | E5: =IF(OR(A5<=Inputs!$B$21,A5>Inputs!$B$21+Configurations!$B$15),0,IF(A5<=Inputs!$B$21+Inputs!$B$5,D5*(1-Inputs!$B$10)*Inputs!$B$19/1000000,D5*Inputs!$B$18/1000000)) -> 0 | F5: =IF(OR(A5<=Inputs!$B$21,A5>Inputs!$B$21+Configurations!$B$15),0,Configurations!$B$12+Configurations!$B$13+Configurations!$B$14+Inputs!$B$20*E5) -> 0 | G5: =E5-F5 -> 0 | H5: =IF(AND(A5>Inputs!$B$21,A5<=Inputs!$B$21+Inputs!$B$12),Capitalization!C$12,0) -> 0 | I5: =G5-H5 -> 0 | J5: =IF(A5<=Inputs!$B$21,"",IF(AND(A5<=Inputs!$B$22,Capitalization!C$18>0),Inputs!$B$25,Inputs!$B$26)) | K5: =IF(A5=0,-Capitalization!C$19,IF(A5<=Inputs!$B$21,0,I5*J5-IF(AND(A5=Inputs!$B$22,Capitalization!C$18>0),Inputs!$B$23,0))) -> -33.749566 | L5: =IF(H5>0,G5/H5,"") | M5: =IF(A5=0,-Capitalization!C$4,IF(A5<=Inputs!$B$21,0,G5)) -> -209
A6: 1 | B6: =IF(A6=0,"Equity",IF(A6<=Inputs!$B$21,"Construction",IF(A6<=Inputs!$B$21+Inputs!$B$5,"Queue wait",IF(A6<=Inputs!$B$21+Configurations!$B$15,"Grid ops","—")))) -> Construction | C6: =IF(A6<=Inputs!$B$21,"",A6-Inputs!$B$21-1) | D6: =IF(OR(A6<=Inputs!$B$21,A6>Inputs!$B$21+Configurations!$B$15),0,Configurations!$B$4*Configurations!$B$5*8760*(1-Configurations!$B$6)^C6*Configurations!$B$7*(1-Configurations!$B$8)) -> 0 | E6: =IF(OR(A6<=Inputs!$B$21,A6>Inputs!$B$21+Configurations!$B$15),0,IF(A6<=Inputs!$B$21+Inputs!$B$5,D6*(1-Inputs!$B$10)*Inputs!$B$19/1000000,D6*Inputs!$B$18/1000000)) -> 0 | F6: =IF(OR(A6<=Inputs!$B$21,A6>Inputs!$B$21+Configurations!$B$15),0,Configurations!$B$12+Configurations!$B$13+Configurations!$B$14+Inputs!$B$20*E6) -> 0 | G6: =E6-F6 -> 0 | H6: =IF(AND(A6>Inputs!$B$21,A6<=Inputs!$B$21+Inputs!$B$12),Capitalization!C$12,0) -> 0 | I6: =G6-H6 -> 0 | J6: =IF(A6<=Inputs!$B$21,"",IF(AND(A6<=Inputs!$B$22,Capitalization!C$18>0),Inputs!$B$25,Inputs!$B$26)) | K6: =IF(A6=0,-Capitalization!C$19,IF(A6<=Inputs!$B$21,0,I6*J6-IF(AND(A6=Inputs!$B$22,Capitalization!C$18>0),Inputs!$B$23,0))) -> 0 | L6: =IF(H6>0,G6/H6,"") | M6: =IF(A6=0,-Capitalization!C$4,IF(A6<=Inputs!$B$21,0,G6)) -> 0
A7: 2 | B7: =IF(A7=0,"Equity",IF(A7<=Inputs!$B$21,"Construction",IF(A7<=Inputs!$B$21+Inputs!$B$5,"Queue wait",IF(A7<=Inputs!$B$21+Configurations!$B$15,"Grid ops","—")))) -> Construction | C7: =IF(A7<=Inputs!$B$21,"",A7-Inputs!$B$21-1) | D7: =IF(OR(A7<=Inputs!$B$21,A7>Inputs!$B$21+Configurations!$B$15),0,Configurations!$B$4*Configurations!$B$5*8760*(1-Configurations!$B$6)^C7*Configurations!$B$7*(1-Configurations!$B$8)) -> 0 | E7: =IF(OR(A7<=Inputs!$B$21,A7>Inputs!$B$21+Configurations!$B$15),0,IF(A7<=Inputs!$B$21+Inputs!$B$5,D7*(1-Inputs!$B$10)*Inputs!$B$19/1000000,D7*Inputs!$B$18/1000000)) -> 0 | F7: =IF(OR(A7<=Inputs!$B$21,A7>Inputs!$B$21+Configurations!$B$15),0,Configurations!$B$12+Configurations!$B$13+Configurations!$B$14+Inputs!$B$20*E7) -> 0 | G7: =E7-F7 -> 0 | H7: =IF(AND(A7>Inputs!$B$21,A7<=Inputs!$B$21+Inputs!$B$12),Capitalization!C$12,0) -> 0 | I7: =G7-H7 -> 0 | J7: =IF(A7<=Inputs!$B$21,"",IF(AND(A7<=Inputs!$B$22,Capitalization!C$18>0),Inputs!$B$25,Inputs!$B$26)) | K7: =IF(A7=0,-Capitalization!C$19,IF(A7<=Inputs!$B$21,0,I7*J7-IF(AND(A7=Inputs!$B$22,Capitalization!C$18>0),Inputs!$B$23,0))) -> 0 | L7: =IF(H7>0,G7/H7,"") | M7: =IF(A7=0,-Capitalization!C$4,IF(A7<=Inputs!$B$21,0,G7)) -> 0
A8: 3 | B8: =IF(A8=0,"Equity",IF(A8<=Inputs!$B$21,"Construction",IF(A8<=Inputs!$B$21+Inputs!$B$5,"Queue wait",IF(A8<=Inputs!$B$21+Configurations!$B$15,"Grid ops","—")))) -> Queue wait | C8: =IF(A8<=Inputs!$B$21,"",A8-Inputs!$B$21-1) -> 0 | D8: =IF(OR(A8<=Inputs!$B$21,A8>Inputs!$B$21+Configurations!$B$15),0,Configurations!$B$4*Configurations!$B$5*8760*(1-Configurations!$B$6)^C8*Configurations!$B$7*(1-Configurations!$B$8)) -> 230179.95 | E8: =IF(OR(A8<=Inputs!$B$21,A8>Inputs!$B$21+Configurations!$B$15),0,IF(A8<=Inputs!$B$21+Inputs!$B$5,D8*(1-Inputs!$B$10)*Inputs!$B$19/1000000,D8*Inputs!$B$18/1000000)) -> 13.672689 | F8: =IF(OR(A8<=Inputs!$B$21,A8>Inputs!$B$21+Configurations!$B$15),0,Configurations!$B$12+Configurations!$B$13+Configurations!$B$14+Inputs!$B$20*E8) -> 5.0430903 | G8: =E8-F8 -> 8.6295987 | H8: =IF(AND(A8>Inputs!$B$21,A8<=Inputs!$B$21+Inputs!$B$12),Capitalization!C$12,0) -> 8.5084163 | I8: =G8-H8 -> 0.12118236 | J8: =IF(A8<=Inputs!$B$21,"",IF(AND(A8<=Inputs!$B$22,Capitalization!C$18>0),Inputs!$B$25,Inputs!$B$26)) -> 0.7 | K8: =IF(A8=0,-Capitalization!C$19,IF(A8<=Inputs!$B$21,0,I8*J8-IF(AND(A8=Inputs!$B$22,Capitalization!C$18>0),Inputs!$B$23,0))) -> 0.084827651 | L8: =IF(H8>0,G8/H8,"") -> 1.0142426 | M8: =IF(A8=0,-Capitalization!C$4,IF(A8<=Inputs!$B$21,0,G8)) -> 8.6295987
A9: 4 | B9: =IF(A9=0,"Equity",IF(A9<=Inputs!$B$21,"Construction",IF(A9<=Inputs!$B$21+Inputs!$B$5,"Queue wait",IF(A9<=Inputs!$B$21+Configurations!$B$15,"Grid ops","—")))) -> Queue wait | C9: =IF(A9<=Inputs!$B$21,"",A9-Inputs!$B$21-1) -> 1 | D9: =IF(OR(A9<=Inputs!$B$21,A9>Inputs!$B$21+Configurations!$B$15),0,Configurations!$B$4*Configurations!$B$5*8760*(1-Configurations!$B$6)^C9*Configurations!$B$7*(1-Configurations!$B$8)) -> 229029.05 | E9: =IF(OR(A9<=Inputs!$B$21,A9>Inputs!$B$21+Configurations!$B$15),0,IF(A9<=Inputs!$B$21+Inputs!$B$5,D9*(1-Inputs!$B$10)*Inputs!$B$19/1000000,D9*Inputs!$B$18/1000000)) -> 13.604326 | F9: =IF(OR(A9<=Inputs!$B$21,A9>Inputs!$B$21+Configurations!$B$15),0,Configurations!$B$12+Configurations!$B$13+Configurations!$B$14+Inputs!$B$20*E9) -> 5.0420649 | G9: =E9-F9 -> 8.5622607 | H9: =IF(AND(A9>Inputs!$B$21,A9<=Inputs!$B$21+Inputs!$B$12),Capitalization!C$12,0) -> 8.5084163 | I9: =G9-H9 -> 0.053844365 | J9: =IF(A9<=Inputs!$B$21,"",IF(AND(A9<=Inputs!$B$22,Capitalization!C$18>0),Inputs!$B$25,Inputs!$B$26)) -> 0.7 | K9: =IF(A9=0,-Capitalization!C$19,IF(A9<=Inputs!$B$21,0,I9*J9-IF(AND(A9=Inputs!$B$22,Capitalization!C$18>0),Inputs!$B$23,0))) -> 0.037691055 | L9: =IF(H9>0,G9/H9,"") -> 1.0063284 | M9: =IF(A9=0,-Capitalization!C$4,IF(A9<=Inputs!$B$21,0,G9)) -> 8.5622607
A10: 5 | B10: =IF(A10=0,"Equity",IF(A10<=Inputs!$B$21,"Construction",IF(A10<=Inputs!$B$21+Inputs!$B$5,"Queue wait",IF(A10<=Inputs!$B$21+Configurations!$B$15,"Grid ops","—")))) -> Queue wait | C10: =IF(A10<=Inputs!$B$21,"",A10-Inputs!$B$21-1) -> 2 | D10: =IF(OR(A10<=Inputs!$B$21,A10>Inputs!$B$21+Configurations!$B$15),0,Configurations!$B$4*Configurations!$B$5*8760*(1-Configurations!$B$6)^C10*Configurations!$B$7*(1-Configurations!$B$8)) -> 227883.9 | E10: =IF(OR(A10<=Inputs!$B$21,A10>Inputs!$B$21+Configurations!$B$15),0,IF(A10<=Inputs!$B$21+Inputs!$B$5,D10*(1-Inputs!$B$10)*Inputs!$B$19/1000000,D10*Inputs!$B$18/1000000)) -> 13.536304 | F10: =IF(OR(A10<=Inputs!$B$21,A10>Inputs!$B$21+Configurations!$B$15),0,Configurations!$B$12+Configurations!$B$13+Configurations!$B$14+Inputs!$B$20*E10) -> 5.0410446 | G10: =E10-F10 -> 8.4952594 | H10: =IF(AND(A10>Inputs!$B$21,A10<=Inputs!$B$21+Inputs!$B$12),Capitalization!C$12,0) -> 8.5084163 | I10: =G10-H10 -> -0.013156939 | J10: =IF(A10<=Inputs!$B$21,"",IF(AND(A10<=Inputs!$B$22,Capitalization!C$18>0),Inputs!$B$25,Inputs!$B$26)) -> 0.7 | K10: =IF(A10=0,-Capitalization!C$19,IF(A10<=Inputs!$B$21,0,I10*J10-IF(AND(A10=Inputs!$B$22,Capitalization!C$18>0),Inputs!$B$23,0))) -> -0.0092098571 | L10: =IF(H10>0,G10/H10,"") -> 0.99845366 | M10: =IF(A10=0,-Capitalization!C$4,IF(A10<=Inputs!$B$21,0,G10)) -> 8.4952594
A11: 6 | B11: =IF(A11=0,"Equity",IF(A11<=Inputs!$B$21,"Construction",IF(A11<=Inputs!$B$21+Inputs!$B$5,"Queue wait",IF(A11<=Inputs!$B$21+Configurations!$B$15,"Grid ops","—")))) -> Queue wait | C11: =IF(A11<=Inputs!$B$21,"",A11-Inputs!$B$21-1) -> 3 | D11: =IF(OR(A11<=Inputs!$B$21,A11>Inputs!$B$21+Configurations!$B$15),0,Configurations!$B$4*Configurations!$B$5*8760*(1-Configurations!$B$6)^C11*Configurations!$B$7*(1-Configurations!$B$8)) -> 226744.49 | E11: =IF(OR(A11<=Inputs!$B$21,A11>Inputs!$B$21+Configurations!$B$15),0,IF(A11<=Inputs!$B$21+Inputs!$B$5,D11*(1-Inputs!$B$10)*Inputs!$B$19/1000000,D11*Inputs!$B$18/1000000)) -> 13.468622 | F11: =IF(OR(A11<=Inputs!$B$21,A11>Inputs!$B$21+Configurations!$B$15),0,Configurations!$B$12+Configurations!$B$13+Configurations!$B$14+Inputs!$B$20*E11) -> 5.0400293 | G11: =E11-F11 -> 8.4285931 | H11: =IF(AND(A11>Inputs!$B$21,A11<=Inputs!$B$21+Inputs!$B$12),Capitalization!C$12,0) -> 8.5084163 | I11: =G11-H11 -> -0.079823236 | J11: =IF(A11<=Inputs!$B$21,"",IF(AND(A11<=Inputs!$B$22,Capitalization!C$18>0),Inputs!$B$25,Inputs!$B$26)) -> 0.7 | K11: =IF(A11=0,-Capitalization!C$19,IF(A11<=Inputs!$B$21,0,I11*J11-IF(AND(A11=Inputs!$B$22,Capitalization!C$18>0),Inputs!$B$23,0))) -> -1.0558763 | L11: =IF(H11>0,G11/H11,"") -> 0.99061832 | M11: =IF(A11=0,-Capitalization!C$4,IF(A11<=Inputs!$B$21,0,G11)) -> 8.4285931
A12: 7 | B12: =IF(A12=0,"Equity",IF(A12<=Inputs!$B$21,"Construction",IF(A12<=Inputs!$B$21+Inputs!$B$5,"Queue wait",IF(A12<=Inputs!$B$21+Configurations!$B$15,"Grid ops","—")))) -> Grid ops | C12: =IF(A12<=Inputs!$B$21,"",A12-Inputs!$B$21-1) -> 4 | D12: =IF(OR(A12<=Inputs!$B$21,A12>Inputs!$B$21+Configurations!$B$15),0,Configurations!$B$4*Configurations!$B$5*8760*(1-Configurations!$B$6)^C12*Configurations!$B$7*(1-Configurations!$B$8)) -> 225610.76 | E12: =IF(OR(A12<=Inputs!$B$21,A12>Inputs!$B$21+Configurations!$B$15),0,IF(A12<=Inputs!$B$21+Inputs!$B$5,D12*(1-Inputs!$B$10)*Inputs!$B$19/1000000,D12*Inputs!$B$18/1000000)) -> 16.243975 | F12: =IF(OR(A12<=Inputs!$B$21,A12>Inputs!$B$21+Configurations!$B$15),0,Configurations!$B$12+Configurations!$B$13+Configurations!$B$14+Inputs!$B$20*E12) -> 5.0816596 | G12: =E12-F12 -> 11.162315 | H12: =IF(AND(A12>Inputs!$B$21,A12<=Inputs!$B$21+Inputs!$B$12),Capitalization!C$12,0) -> 8.5084163 | I12: =G12-H12 -> 2.653899 | J12: =IF(A12<=Inputs!$B$21,"",IF(AND(A12<=Inputs!$B$22,Capitalization!C$18>0),Inputs!$B$25,Inputs!$B$26)) -> 0.975 | K12: =IF(A12=0,-Capitalization!C$19,IF(A12<=Inputs!$B$21,0,I12*J12-IF(AND(A12=Inputs!$B$22,Capitalization!C$18>0),Inputs!$B$23,0))) -> 2.5875515 | L12: =IF(H12>0,G12/H12,"") -> 1.3119146 | M12: =IF(A12=0,-Capitalization!C$4,IF(A12<=Inputs!$B$21,0,G12)) -> 11.162315
A13: 8 | B13: =IF(A13=0,"Equity",IF(A13<=Inputs!$B$21,"Construction",IF(A13<=Inputs!$B$21+Inputs!$B$5,"Queue wait",IF(A13<=Inputs!$B$21+Configurations!$B$15,"Grid ops","—")))) -> Grid ops | C13: =IF(A13<=Inputs!$B$21,"",A13-Inputs!$B$21-1) -> 5 | D13: =IF(OR(A13<=Inputs!$B$21,A13>Inputs!$B$21+Configurations!$B$15),0,Configurations!$B$4*Configurations!$B$5*8760*(1-Configurations!$B$6)^C13*Configurations!$B$7*(1-Configurations!$B$8)) -> 224482.71 | E13: =IF(OR(A13<=Inputs!$B$21,A13>Inputs!$B$21+Configurations!$B$15),0,IF(A13<=Inputs!$B$21+Inputs!$B$5,D13*(1-Inputs!$B$10)*Inputs!$B$19/1000000,D13*Inputs!$B$18/1000000)) -> 16.162755 | F13: =IF(OR(A13<=Inputs!$B$21,A13>Inputs!$B$21+Configurations!$B$15),0,Configurations!$B$12+Configurations!$B$13+Configurations!$B$14+Inputs!$B$20*E13) -> 5.0804413 | G13: =E13-F13 -> 11.082314 | H13: =IF(AND(A13>Inputs!$B$21,A13<=Inputs!$B$21+Inputs!$B$12),Capitalization!C$12,0) -> 8.5084163 | I13: =G13-H13 -> 2.5738974 | J13: =IF(A13<=Inputs!$B$21,"",IF(AND(A13<=Inputs!$B$22,Capitalization!C$18>0),Inputs!$B$25,Inputs!$B$26)) -> 0.975 | K13: =IF(A13=0,-Capitalization!C$19,IF(A13<=Inputs!$B$21,0,I13*J13-IF(AND(A13=Inputs!$B$22,Capitalization!C$18>0),Inputs!$B$23,0))) -> 2.50955 | L13: =IF(H13>0,G13/H13,"") -> 1.3025119 | M13: =IF(A13=0,-Capitalization!C$4,IF(A13<=Inputs!$B$21,0,G13)) -> 11.082314
A14: 9 | B14: =IF(A14=0,"Equity",IF(A14<=Inputs!$B$21,"Construction",IF(A14<=Inputs!$B$21+Inputs!$B$5,"Queue wait",IF(A14<=Inputs!$B$21+Configurations!$B$15,"Grid ops","—")))) -> Grid ops | C14: =IF(A14<=Inputs!$B$21,"",A14-Inputs!$B$21-1) -> 6 | D14: =IF(OR(A14<=Inputs!$B$21,A14>Inputs!$B$21+Configurations!$B$15),0,Configurations!$B$4*Configurations!$B$5*8760*(1-Configurations!$B$6)^C14*Configurations!$B$7*(1-Configurations!$B$8)) -> 223360.3 | E14: =IF(OR(A14<=Inputs!$B$21,A14>Inputs!$B$21+Configurations!$B$15),0,IF(A14<=Inputs!$B$21+Inputs!$B$5,D14*(1-Inputs!$B$10)*Inputs!$B$19/1000000,D14*Inputs!$B$18/1000000)) -> 16.081941 | F14: =IF(OR(A14<=Inputs!$B$21,A14>Inputs!$B$21+Configurations!$B$15),0,Configurations!$B$12+Configurations!$B$13+Configurations!$B$14+Inputs!$B$20*E14) -> 5.0792291 | G14: =E14-F14 -> 11.002712 | H14: =IF(AND(A14>Inputs!$B$21,A14<=Inputs!$B$21+Inputs!$B$12),Capitalization!C$12,0) -> 8.5084163 | I14: =G14-H14 -> 2.4942958 | J14: =IF(A14<=Inputs!$B$21,"",IF(AND(A14<=Inputs!$B$22,Capitalization!C$18>0),Inputs!$B$25,Inputs!$B$26)) -> 0.975 | K14: =IF(A14=0,-Capitalization!C$19,IF(A14<=Inputs!$B$21,0,I14*J14-IF(AND(A14=Inputs!$B$22,Capitalization!C$18>0),Inputs!$B$23,0))) -> 2.4319384 | L14: =IF(H14>0,G14/H14,"") -> 1.2931563 | M14: =IF(A14=0,-Capitalization!C$4,IF(A14<=Inputs!$B$21,0,G14)) -> 11.002712
A15: 10 | B15: =IF(A15=0,"Equity",IF(A15<=Inputs!$B$21,"Construction",IF(A15<=Inputs!$B$21+Inputs!$B$5,"Queue wait",IF(A15<=Inputs!$B$21+Configurations!$B$15,"Grid ops","—")))) -> Grid ops | C15: =IF(A15<=Inputs!$B$21,"",A15-Inputs!$B$21-1) -> 7 | D15: =IF(OR(A15<=Inputs!$B$21,A15>Inputs!$B$21+Configurations!$B$15),0,Configurations!$B$4*Configurations!$B$5*8760*(1-Configurations!$B$6)^C15*Configurations!$B$7*(1-Configurations!$B$8)) -> 222243.49 | E15: =IF(OR(A15<=Inputs!$B$21,A15>Inputs!$B$21+Configurations!$B$15),0,IF(A15<=Inputs!$B$21+Inputs!$B$5,D15*(1-Inputs!$B$10)*Inputs!$B$19/1000000,D15*Inputs!$B$18/1000000)) -> 16.001532 | F15: =IF(OR(A15<=Inputs!$B$21,A15>Inputs!$B$21+Configurations!$B$15),0,Configurations!$B$12+Configurations!$B$13+Configurations!$B$14+Inputs!$B$20*E15) -> 5.078023 | G15: =E15-F15 -> 10.923509 | H15: =IF(AND(A15>Inputs!$B$21,A15<=Inputs!$B$21+Inputs!$B$12),Capitalization!C$12,0) -> 8.5084163 | I15: =G15-H15 -> 2.4150923 | J15: =IF(A15<=Inputs!$B$21,"",IF(AND(A15<=Inputs!$B$22,Capitalization!C$18>0),Inputs!$B$25,Inputs!$B$26)) -> 0.975 | K15: =IF(A15=0,-Capitalization!C$19,IF(A15<=Inputs!$B$21,0,I15*J15-IF(AND(A15=Inputs!$B$22,Capitalization!C$18>0),Inputs!$B$23,0))) -> 2.354715 | L15: =IF(H15>0,G15/H15,"") -> 1.2838474 | M15: =IF(A15=0,-Capitalization!C$4,IF(A15<=Inputs!$B$21,0,G15)) -> 10.923509
A16: 11 | B16: =IF(A16=0,"Equity",IF(A16<=Inputs!$B$21,"Construction",IF(A16<=Inputs!$B$21+Inputs!$B$5,"Queue wait",IF(A16<=Inputs!$B$21+Configurations!$B$15,"Grid ops","—")))) -> Grid ops | C16: =IF(A16<=Inputs!$B$21,"",A16-Inputs!$B$21-1) -> 8 | D16: =IF(OR(A16<=Inputs!$B$21,A16>Inputs!$B$21+Configurations!$B$15),0,Configurations!$B$4*Configurations!$B$5*8760*(1-Configurations!$B$6)^C16*Configurations!$B$7*(1-Configurations!$B$8)) -> 221132.28 | E16: =IF(OR(A16<=Inputs!$B$21,A16>Inputs!$B$21+Configurations!$B$15),0,IF(A16<=Inputs!$B$21+Inputs!$B$5,D16*(1-Inputs!$B$10)*Inputs!$B$19/1000000,D16*Inputs!$B$18/1000000)) -> 15.921524 | F16: =IF(OR(A16<=Inputs!$B$21,A16>Inputs!$B$21+Configurations!$B$15),0,Configurations!$B$12+Configurations!$B$13+Configurations!$B$14+Inputs!$B$20*E16) -> 5.0768229 | G16: =E16-F16 -> 10.844701 | H16: =IF(AND(A16>Inputs!$B$21,A16<=Inputs!$B$21+Inputs!$B$12),Capitalization!C$12,0) -> 8.5084163 | I16: =G16-H16 -> 2.3362847 | J16: =IF(A16<=Inputs!$B$21,"",IF(AND(A16<=Inputs!$B$22,Capitalization!C$18>0),Inputs!$B$25,Inputs!$B$26)) -> 0.975 | K16: =IF(A16=0,-Capitalization!C$19,IF(A16<=Inputs!$B$21,0,I16*J16-IF(AND(A16=Inputs!$B$22,Capitalization!C$18>0),Inputs!$B$23,0))) -> 2.2778776 | L16: =IF(H16>0,G16/H16,"") -> 1.2745851 | M16: =IF(A16=0,-Capitalization!C$4,IF(A16<=Inputs!$B$21,0,G16)) -> 10.844701
... A37: 32 | B37: =IF(A37=0,"Equity",IF(A37<=Inputs!$B$21,"Construction",IF(A37<=Inputs!$B$21+Inputs!$B$5,"Queue wait",IF(A37<=Inputs!$B$21+Configurations!$B$15,"Grid ops","—")))) -> — | C37: =IF(A37<=Inputs!$B$21,"",A37-Inputs!$B$21-1) -> 29 | D37: =IF(OR(A37<=Inputs!$B$21,A37>Inputs!$B$21+Configurations!$B$15),0,Configurations!$B$4*Configurations!$B$5*8760*(1-Configurations!$B$6)^C37*Configurations!$B$7*(1-Configurations!$B$8)) -> 0 | E37: =IF(OR(A37<=Inputs!$B$21,A37>Inputs!$B$21+Configurations!$B$15),0,IF(A37<=Inputs!$B$21+Inputs!$B$5,D37*(1-Inputs!$B$10)*Inputs!$B$19/1000000,D37*Inputs!$B$18/1000000)) -> 0 | F37: =IF(OR(A37<=Inputs!$B$21,A37>Inputs!$B$21+Configurations!$B$15),0,Configurations!$B$12+Configurations!$B$13+Configurations!$B$14+Inputs!$B$20*E37) -> 0 | G37: =E37-F37 -> 0 | H37: =IF(AND(A37>Inputs!$B$21,A37<=Inputs!$B$21+Inputs!$B$12),Capitalization!C$12,0) -> 0 | I37: =G37-H37 -> 0 | J37: =IF(A37<=Inputs!$B$21,"",IF(AND(A37<=Inputs!$B$22,Capitalization!C$18>0),Inputs!$B$25,Inputs!$B$26)) -> 0.975 | K37: =IF(A37=0,-Capitalization!C$19,IF(A37<=Inputs!$B$21,0,I37*J37-IF(AND(A37=Inputs!$B$22,Capitalization!C$18>0),Inputs!$B$23,0))) -> 0 | L37: =IF(H37>0,G37/H37,"") | M37: =IF(A37=0,-Capitalization!C$4,IF(A37<=Inputs!$B$21,0,G37)) -> 0

Sheet WindBase
A1: WindBase — annual cash flow waterfall ($mm)
A2: Developer levered IRR: | B2: =IRR(K5:K37) -> 0.076471682 | C2: Unlevered (project) IRR: | D2: =IRR(M5:M37) -> 0.02031468 | E2: NPV of dev cash @ discount rate ($mm): | F2: =K5+NPV(Inputs!$B$24,K6:K37) -> -2.4701198
A4: Year | B4: Phase | C4: Op yr | D4: Net energy (MWh) | E4: Revenue | F4: OPEX | G4: EBITDA | H4: Debt service | I4: Distributable cash | J4: Dev share | K4: Dev cash flow | L4: DSCR | M4: Project CF (unlevered)
A5: 0 | B5: =IF(A5=0,"Equity",IF(A5<=Inputs!$B$21,"Construction",IF(A5<=Inputs!$B$21+Inputs!$B$5,"Queue wait",IF(A5<=Inputs!$B$21+Configurations!$C$15,"Grid ops","—")))) -> Equity | C5: =IF(A5<=Inputs!$B$21,"",A5-Inputs!$B$21-1) | D5: =IF(OR(A5<=Inputs!$B$21,A5>Inputs!$B$21+Configurations!$C$15),0,Configurations!$C$4*Configurations!$C$5*8760*(1-Configurations!$C$6)^C5*Configurations!$C$7*(1-Configurations!$C$8)) -> 0 | E5: =IF(OR(A5<=Inputs!$B$21,A5>Inputs!$B$21+Configurations!$C$15),0,IF(A5<=Inputs!$B$21+Inputs!$B$5,0,D5*Inputs!$B$18/1000000)) -> 0 | F5: =IF(OR(A5<=Inputs!$B$21,A5>Inputs!$B$21+Configurations!$C$15),0,IF(A5<=Inputs!$B$21+Inputs!$B$5,Configurations!$C$13,Configurations!$C$12+Configurations!$C$13+Inputs!$B$20*E5)) -> 0 | G5: =E5-F5 -> 0 | H5: =IF(AND(A5>Inputs!$B$21,A5<=Inputs!$B$21+Inputs!$B$12),Capitalization!D$12,0) -> 0 | I5: =G5-H5 -> 0 | J5: =IF(A5<=Inputs!$B$21,"",IF(AND(A5<=Inputs!$B$22,Capitalization!D$18>0),Inputs!$B$25,Inputs!$B$26)) | K5: =IF(A5=0,-Capitalization!D$19,IF(A5<=Inputs!$B$21,0,I5*J5-IF(AND(A5=Inputs!$B$22,Capitalization!D$18>0),Inputs!$B$23,0))) -> -23.543402 | L5: =IF(H5>0,G5/H5,"") | M5: =IF(A5=0,-Capitalization!D$4,IF(A5<=Inputs!$B$21,0,G5)) -> -321.4
A6: 1 | B6: =IF(A6=0,"Equity",IF(A6<=Inputs!$B$21,"Construction",IF(A6<=Inputs!$B$21+Inputs!$B$5,"Queue wait",IF(A6<=Inputs!$B$21+Configurations!$C$15,"Grid ops","—")))) -> Construction | C6: =IF(A6<=Inputs!$B$21,"",A6-Inputs!$B$21-1) | D6: =IF(OR(A6<=Inputs!$B$21,A6>Inputs!$B$21+Configurations!$C$15),0,Configurations!$C$4*Configurations!$C$5*8760*(1-Configurations!$C$6)^C6*Configurations!$C$7*(1-Configurations!$C$8)) -> 0 | E6: =IF(OR(A6<=Inputs!$B$21,A6>Inputs!$B$21+Configurations!$C$15),0,IF(A6<=Inputs!$B$21+Inputs!$B$5,0,D6*Inputs!$B$18/1000000)) -> 0 | F6: =IF(OR(A6<=Inputs!$B$21,A6>Inputs!$B$21+Configurations!$C$15),0,IF(A6<=Inputs!$B$21+Inputs!$B$5,Configurations!$C$13,Configurations!$C$12+Configurations!$C$13+Inputs!$B$20*E6)) -> 0 | G6: =E6-F6 -> 0 | H6: =IF(AND(A6>Inputs!$B$21,A6<=Inputs!$B$21+Inputs!$B$12),Capitalization!D$12,0) -> 0 | I6: =G6-H6 -> 0 | J6: =IF(A6<=Inputs!$B$21,"",IF(AND(A6<=Inputs!$B$22,Capitalization!D$18>0),Inputs!$B$25,Inputs!$B$26)) | K6: =IF(A6=0,-Capitalization!D$19,IF(A6<=Inputs!$B$21,0,I6*J6-IF(AND(A6=Inputs!$B$22,Capitalization!D$18>0),Inputs!$B$23,0))) -> 0 | L6: =IF(H6>0,G6/H6,"") | M6: =IF(A6=0,-Capitalization!D$4,IF(A6<=Inputs!$B$21,0,G6)) -> 0
A7: 2 | B7: =IF(A7=0,"Equity",IF(A7<=Inputs!$B$21,"Construction",IF(A7<=Inputs!$B$21+Inputs!$B$5,"Queue wait",IF(A7<=Inputs!$B$21+Configurations!$C$15,"Grid ops","—")))) -> Construction | C7: =IF(A7<=Inputs!$B$21,"",A7-Inputs!$B$21-1) | D7: =IF(OR(A7<=Inputs!$B$21,A7>Inputs!$B$21+Configurations!$C$15),0,Configurations!$C$4*Configurations!$C$5*8760*(1-Configurations!$C$6)^C7*Configurations!$C$7*(1-Configurations!$C$8)) -> 0 | E7: =IF(OR(A7<=Inputs!$B$21,A7>Inputs!$B$21+Configurations!$C$15),0,IF(A7<=Inputs!$B$21+Inputs!$B$5,0,D7*Inputs!$B$18/1000000)) -> 0 | F7: =IF(OR(A7<=Inputs!$B$21,A7>Inputs!$B$21+Configurations!$C$15),0,IF(A7<=Inputs!$B$21+Inputs!$B$5,Configurations!$C$13,Configurations!$C$12+Configurations!$C$13+Inputs!$B$20*E7)) -> 0 | G7: =E7-F7 -> 0 | H7: =IF(AND(A7>Inputs!$B$21,A7<=Inputs!$B$21+Inputs!$B$12),Capitalization!D$12,0) -> 0 | I7: =G7-H7 -> 0 | J7: =IF(A7<=Inputs!$B$21,"",IF(AND(A7<=Inputs!$B$22,Capitalization!D$18>0),Inputs!$B$25,Inputs!$B$26)) | K7: =IF(A7=0,-Capitalization!D$19,IF(A7<=Inputs!$B$21,0,I7*J7-IF(AND(A7=Inputs!$B$22,Capitalization!D$18>0),Inputs!$B$23,0))) -> 0 | L7: =IF(H7>0,G7/H7,"") | M7: =IF(A7=0,-Capitalization!D$4,IF(A7<=Inputs!$B$21,0,G7)) -> 0
A8: 3 | B8: =IF(A8=0,"Equity",IF(A8<=Inputs!$B$21,"Construction",IF(A8<=Inputs!$B$21+Inputs!$B$5,"Queue wait",IF(A8<=Inputs!$B$21+Configurations!$C$15,"Grid ops","—")))) -> Queue wait | C8: =IF(A8<=Inputs!$B$21,"",A8-Inputs!$B$21-1) -> 0 | D8: =IF(OR(A8<=Inputs!$B$21,A8>Inputs!$B$21+Configurations!$C$15),0,Configurations!$C$4*Configurations!$C$5*8760*(1-Configurations!$C$6)^C8*Configurations!$C$7*(1-Configurations!$C$8)) -> 430466.4 | E8: =IF(OR(A8<=Inputs!$B$21,A8>Inputs!$B$21+Configurations!$C$15),0,IF(A8<=Inputs!$B$21+Inputs!$B$5,0,D8*Inputs!$B$18/1000000)) -> 0 | F8: =IF(OR(A8<=Inputs!$B$21,A8>Inputs!$B$21+Configurations!$C$15),0,IF(A8<=Inputs!$B$21+Inputs!$B$5,Configurations!$C$13,Configurations!$C$12+Configurations!$C$13+Inputs!$B$20*E8)) -> 1.586 | G8: =E8-F8 -> -1.586 | H8: =IF(AND(A8>Inputs!$B$21,A8<=Inputs!$B$21+Inputs!$B$12),Capitalization!D$12,0) -> 14.791995 | I8: =G8-H8 -> -16.377995 | J8: =IF(A8<=Inputs!$B$21,"",IF(AND(A8<=Inputs!$B$22,Capitalization!D$18>0),Inputs!$B$25,Inputs!$B$26)) -> 0.7 | K8: =IF(A8=0,-Capitalization!D$19,IF(A8<=Inputs!$B$21,0,I8*J8-IF(AND(A8=Inputs!$B$22,Capitalization!D$18>0),Inputs!$B$23,0))) -> -11.464597 | L8: =IF(H8>0,G8/H8,"") -> -0.10722015 | M8: =IF(A8=0,-Capitalization!D$4,IF(A8<=Inputs!$B$21,0,G8)) -> -1.586
A9: 4 | B9: =IF(A9=0,"Equity",IF(A9<=Inputs!$B$21,"Construction",IF(A9<=Inputs!$B$21+Inputs!$B$5,"Queue wait",IF(A9<=Inputs!$B$21+Configurations!$C$15,"Grid ops","—")))) -> Queue wait | C9: =IF(A9<=Inputs!$B$21,"",A9-Inputs!$B$21-1) -> 1 | D9: =IF(OR(A9<=Inputs!$B$21,A9>Inputs!$B$21+Configurations!$C$15),0,Configurations!$C$4*Configurations!$C$5*8760*(1-Configurations!$C$6)^C9*Configurations!$C$7*(1-Configurations!$C$8)) -> 429605.47 | E9: =IF(OR(A9<=Inputs!$B$21,A9>Inputs!$B$21+Configurations!$C$15),0,IF(A9<=Inputs!$B$21+Inputs!$B$5,0,D9*Inputs!$B$18/1000000)) -> 0 | F9: =IF(OR(A9<=Inputs!$B$21,A9>Inputs!$B$21+Configurations!$C$15),0,IF(A9<=Inputs!$B$21+Inputs!$B$5,Configurations!$C$13,Configurations!$C$12+Configurations!$C$13+Inputs!$B$20*E9)) -> 1.586 | G9: =E9-F9 -> -1.586 | H9: =IF(AND(A9>Inputs!$B$21,A9<=Inputs!$B$21+Inputs!$B$12),Capitalization!D$12,0) -> 14.791995 | I9: =G9-H9 -> -16.377995 | J9: =IF(A9<=Inputs!$B$21,"",IF(AND(A9<=Inputs!$B$22,Capitalization!D$18>0),Inputs!$B$25,Inputs!$B$26)) -> 0.7 | K9: =IF(A9=0,-Capitalization!D$19,IF(A9<=Inputs!$B$21,0,I9*J9-IF(AND(A9=Inputs!$B$22,Capitalization!D$18>0),Inputs!$B$23,0))) -> -11.464597 | L9: =IF(H9>0,G9/H9,"") -> -0.10722015 | M9: =IF(A9=0,-Capitalization!D$4,IF(A9<=Inputs!$B$21,0,G9)) -> -1.586
A10: 5 | B10: =IF(A10=0,"Equity",IF(A10<=Inputs!$B$21,"Construction",IF(A10<=Inputs!$B$21+Inputs!$B$5,"Queue wait",IF(A10<=Inputs!$B$21+Configurations!$C$15,"Grid ops","—")))) -> Queue wait | C10: =IF(A10<=Inputs!$B$21,"",A10-Inputs!$B$21-1) -> 2 | D10: =IF(OR(A10<=Inputs!$B$21,A10>Inputs!$B$21+Configurations!$C$15),0,Configurations!$C$4*Configurations!$C$5*8760*(1-Configurations!$C$6)^C10*Configurations!$C$7*(1-Configurations!$C$8)) -> 428746.26 | E10: =IF(OR(A10<=Inputs!$B$21,A10>Inputs!$B$21+Configurations!$C$15),0,IF(A10<=Inputs!$B$21+Inputs!$B$5,0,D10*Inputs!$B$18/1000000)) -> 0 | F10: =IF(OR(A10<=Inputs!$B$21,A10>Inputs!$B$21+Configurations!$C$15),0,IF(A10<=Inputs!$B$21+Inputs!$B$5,Configurations!$C$13,Configurations!$C$12+Configurations!$C$13+Inputs!$B$20*E10)) -> 1.586 | G10: =E10-F10 -> -1.586 | H10: =IF(AND(A10>Inputs!$B$21,A10<=Inputs!$B$21+Inputs!$B$12),Capitalization!D$12,0) -> 14.791995 | I10: =G10-H10 -> -16.377995 | J10: =IF(A10<=Inputs!$B$21,"",IF(AND(A10<=Inputs!$B$22,Capitalization!D$18>0),Inputs!$B$25,Inputs!$B$26)) -> 0.7 | K10: =IF(A10=0,-Capitalization!D$19,IF(A10<=Inputs!$B$21,0,I10*J10-IF(AND(A10=Inputs!$B$22,Capitalization!D$18>0),Inputs!$B$23,0))) -> -11.464597 | L10: =IF(H10>0,G10/H10,"") -> -0.10722015 | M10: =IF(A10=0,-Capitalization!D$4,IF(A10<=Inputs!$B$21,0,G10)) -> -1.586
A11: 6 | B11: =IF(A11=0,"Equity",IF(A11<=Inputs!$B$21,"Construction",IF(A11<=Inputs!$B$21+Inputs!$B$5,"Queue wait",IF(A11<=Inputs!$B$21+Configurations!$C$15,"Grid ops","—")))) -> Queue wait | C11: =IF(A11<=Inputs!$B$21,"",A11-Inputs!$B$21-1) -> 3 | D11: =IF(OR(A11<=Inputs!$B$21,A11>Inputs!$B$21+Configurations!$C$15),0,Configurations!$C$4*Configurations!$C$5*8760*(1-Configurations!$C$6)^C11*Configurations!$C$7*(1-Configurations!$C$8)) -> 427888.76 | E11: =IF(OR(A11<=Inputs!$B$21,A11>Inputs!$B$21+Configurations!$C$15),0,IF(A11<=Inputs!$B$21+Inputs!$B$5,0,D11*Inputs!$B$18/1000000)) -> 0 | F11: =IF(OR(A11<=Inputs!$B$21,A11>Inputs!$B$21+Configurations!$C$15),0,IF(A11<=Inputs!$B$21+Inputs!$B$5,Configurations!$C$13,Configurations!$C$12+Configurations!$C$13+Inputs!$B$20*E11)) -> 1.586 | G11: =E11-F11 -> -1.586 | H11: =IF(AND(A11>Inputs!$B$21,A11<=Inputs!$B$21+Inputs!$B$12),Capitalization!D$12,0) -> 14.791995 | I11: =G11-H11 -> -16.377995 | J11: =IF(A11<=Inputs!$B$21,"",IF(AND(A11<=Inputs!$B$22,Capitalization!D$18>0),Inputs!$B$25,Inputs!$B$26)) -> 0.7 | K11: =IF(A11=0,-Capitalization!D$19,IF(A11<=Inputs!$B$21,0,I11*J11-IF(AND(A11=Inputs!$B$22,Capitalization!D$18>0),Inputs!$B$23,0))) -> -12.464597 | L11: =IF(H11>0,G11/H11,"") -> -0.10722015 | M11: =IF(A11=0,-Capitalization!D$4,IF(A11<=Inputs!$B$21,0,G11)) -> -1.586
A12: 7 | B12: =IF(A12=0,"Equity",IF(A12<=Inputs!$B$21,"Construction",IF(A12<=Inputs!$B$21+Inputs!$B$5,"Queue wait",IF(A12<=Inputs!$B$21+Configurations!$C$15,"Grid ops","—")))) -> Grid ops | C12: =IF(A12<=Inputs!$B$21,"",A12-Inputs!$B$21-1) -> 4 | D12: =IF(OR(A12<=Inputs!$B$21,A12>Inputs!$B$21+Configurations!$C$15),0,Configurations!$C$4*Configurations!$C$5*8760*(1-Configurations!$C$6)^C12*Configurations!$C$7*(1-Configurations!$C$8)) -> 427032.99 | E12: =IF(OR(A12<=Inputs!$B$21,A12>Inputs!$B$21+Configurations!$C$15),0,IF(A12<=Inputs!$B$21+Inputs!$B$5,0,D12*Inputs!$B$18/1000000)) -> 30.746375 | F12: =IF(OR(A12<=Inputs!$B$21,A12>Inputs!$B$21+Configurations!$C$15),0,IF(A12<=Inputs!$B$21+Inputs!$B$5,Configurations!$C$13,Configurations!$C$12+Configurations!$C$13+Inputs!$B$20*E12)) -> 8.4221956 | G12: =E12-F12 -> 22.324179 | H12: =IF(AND(A12>Inputs!$B$21,A12<=Inputs!$B$21+Inputs!$B$12),Capitalization!D$12,0) -> 14.791995 | I12: =G12-H12 -> 7.5321842 | J12: =IF(A12<=Inputs!$B$21,"",IF(AND(A12<=Inputs!$B$22,Capitalization!D$18>0),Inputs!$B$25,Inputs!$B$26)) -> 0.975 | K12: =IF(A12=0,-Capitalization!D$19,IF(A12<=Inputs!$B$21,0,I12*J12-IF(AND(A12=Inputs!$B$22,Capitalization!D$18>0),Inputs!$B$23,0))) -> 7.3438796 | L12: =IF(H12>0,G12/H12,"") -> 1.5092068 | M12: =IF(A12=0,-Capitalization!D$4,IF(A12<=Inputs!$B$21,0,G12)) -> 22.324179
A13: 8 | B13: =IF(A13=0,"Equity",IF(A13<=Inputs!$B$21,"Construction",IF(A13<=Inputs!$B$21+Inputs!$B$5,"Queue wait",IF(A13<=Inputs!$B$21+Configurations!$C$15,"Grid ops","—")))) -> Grid ops | C13: =IF(A13<=Inputs!$B$21,"",A13-Inputs!$B$21-1) -> 5 | D13: =IF(OR(A13<=Inputs!$B$21,A13>Inputs!$B$21+Configurations!$C$15),0,Configurations!$C$4*Configurations!$C$5*8760*(1-Configurations!$C$6)^C13*Configurations!$C$7*(1-Configurations!$C$8)) -> 426178.92 | E13: =IF(OR(A13<=Inputs!$B$21,A13>Inputs!$B$21+Configurations!$C$15),0,IF(A13<=Inputs!$B$21+Inputs!$B$5,0,D13*Inputs!$B$18/1000000)) -> 30.684882 | F13: =IF(OR(A13<=Inputs!$B$21,A13>Inputs!$B$21+Configurations!$C$15),0,IF(A13<=Inputs!$B$21+Inputs!$B$5,Configurations!$C$13,Configurations!$C$12+Configurations!$C$13+Inputs!$B$20*E13)) -> 8.4212732 | G13: =E13-F13 -> 22.263609 | H13: =IF(AND(A13>Inputs!$B$21,A13<=Inputs!$B$21+Inputs!$B$12),Capitalization!D$12,0) -> 14.791995 | I13: =G13-H13 -> 7.4716139 | J13: =IF(A13<=Inputs!$B$21,"",IF(AND(A13<=Inputs!$B$22,Capitalization!D$18>0),Inputs!$B$25,Inputs!$B$26)) -> 0.975 | K13: =IF(A13=0,-Capitalization!D$19,IF(A13<=Inputs!$B$21,0,I13*J13-IF(AND(A13=Inputs!$B$22,Capitalization!D$18>0),Inputs!$B$23,0))) -> 7.2848235 | L13: =IF(H13>0,G13/H13,"") -> 1.505112 | M13: =IF(A13=0,-Capitalization!D$4,IF(A13<=Inputs!$B$21,0,G13)) -> 22.263609
A14: 9 | B14: =IF(A14=0,"Equity",IF(A14<=Inputs!$B$21,"Construction",IF(A14<=Inputs!$B$21+Inputs!$B$5,"Queue wait",IF(A14<=Inputs!$B$21+Configurations!$C$15,"Grid ops","—")))) -> Grid ops | C14: =IF(A14<=Inputs!$B$21,"",A14-Inputs!$B$21-1) -> 6 | D14: =IF(OR(A14<=Inputs!$B$21,A14>Inputs!$B$21+Configurations!$C$15),0,Configurations!$C$4*Configurations!$C$5*8760*(1-Configurations!$C$6)^C14*Configurations!$C$7*(1-Configurations!$C$8)) -> 425326.56 | E14: =IF(OR(A14<=Inputs!$B$21,A14>Inputs!$B$21+Configurations!$C$15),0,IF(A14<=Inputs!$B$21+Inputs!$B$5,0,D14*Inputs!$B$18/1000000)) -> 30.623512 | F14: =IF(OR(A14<=Inputs!$B$21,A14>Inputs!$B$21+Configurations!$C$15),0,IF(A14<=Inputs!$B$21+Inputs!$B$5,Configurations!$C$13,Configurations!$C$12+Configurations!$C$13+Inputs!$B$20*E14)) -> 8.4203527 | G14: =E14-F14 -> 22.20316 | H14: =IF(AND(A14>Inputs!$B$21,A14<=Inputs!$B$21+Inputs!$B$12),Capitalization!D$12,0) -> 14.791995 | I14: =G14-H14 -> 7.4111646 | J14: =IF(A14<=Inputs!$B$21,"",IF(AND(A14<=Inputs!$B$22,Capitalization!D$18>0),Inputs!$B$25,Inputs!$B$26)) -> 0.975 | K14: =IF(A14=0,-Capitalization!D$19,IF(A14<=Inputs!$B$21,0,I14*J14-IF(AND(A14=Inputs!$B$22,Capitalization!D$18>0),Inputs!$B$23,0))) -> 7.2258855 | L14: =IF(H14>0,G14/H14,"") -> 1.5010254 | M14: =IF(A14=0,-Capitalization!D$4,IF(A14<=Inputs!$B$21,0,G14)) -> 22.20316
